Workbook

Sheet Upload
A2: PRICE LIST UPLOAD FORMAT TO CCC INFO
I3: Debut
A4: Category | B4: model | C4: specification | D4: debut | E4: price | F4: is_nla | G4: Remark | I4: Year | J4: Month | K4: string | M4: MODEL | N4: SPECIFICATION | O4: DEBUT | P4: PRICE | Q4: IS_NLA | R4: REMARK
A5: =VLOOKUP(LEFT(M5,3),Category!$G$3:$H$73,2,0) -> TELEVISION | B5: =UPPER(M5) -> 2T-C24DC1I | C5: =IF(OR(N5="",N5=0),"",N5) -> HD-Ready . DVB-T2 Ready,USB Music | D5: =IFERROR(K5,"") -> 2021-04-01 | E5: =P5 -> 1496280 | F5: =IF(O5="DISC",1,0) -> 0 | G5: =IF(R5="","",R5) | I5: =IF(YEAR(O5)=2022,2000+DAY(O5),YEAR(O5)) -> 2021 | J5: =IF(MONTH(O5)<10,"0"&MONTH(O5),MONTH(O5)) -> 04 | K5: =I5&"-"&J5&"-01" -> 2021-04-01 | M5: 2T-C24DC1I | N5: HD-Ready . DVB-T2 Ready,USB Music | O5: 44287 | P5: 1496280
A6: =VLOOKUP(LEFT(M6,3),Category!$G$3:$H$73,2,0) -> TELEVISION | B6: =UPPER(M6) -> 2T-C24DD1I | C6: =IF(OR(N6="",N6=0),"",N6) -> HD-Ready . DVB-T2 Ready,USB Movie | D6: =IFERROR(K6,"") -> 2021-04-01 | E6: =P6 -> 1509600 | F6: =IF(O6="DISC",1,0) -> 0 | G6: =IF(R6="","",R6) | I6: =IF(YEAR(O6)=2022,2000+DAY(O6),YEAR(O6)) -> 2021 | J6: =IF(MONTH(O6)<10,"0"&MONTH(O6),MONTH(O6)) -> 04 | K6: =I6&"-"&J6&"-01" -> 2021-04-01 | M6: 2T-C24DD1I | N6: HD-Ready . DVB-T2 Ready,USB Movie | O6: 44287 | P6: 1509600
A7: =VLOOKUP(LEFT(M7,3),Category!$G$3:$H$73,2,0) -> TELEVISION | B7: =UPPER(M7) -> 2T-C24DD1I-TT | C7: =IF(OR(N7="",N7=0),"",N7) -> HD-Ready . DVB-T2 Ready,USB Movie | D7: =IFERROR(K7,"") -> 2021-04-01 | E7: =P7 -> 1509600 | F7: =IF(O7="DISC",1,0) -> 0 | G7: =IF(R7="","",R7) | I7: =IF(YEAR(O7)=2022,2000+DAY(O7),YEAR(O7)) -> 2021 | J7: =IF(MONTH(O7)<10,"0"&MONTH(O7),MONTH(O7)) -> 04 | K7: =I7&"-"&J7&"-01" -> 2021-04-01 | M7: 2T-C24DD1I-TT | N7: HD-Ready . DVB-T2 Ready,USB Movie | O7: 44287 | P7: 1509600
A8: =VLOOKUP(LEFT(M8,3),Category!$G$3:$H$73,2,0) -> TELEVISION | B8: =UPPER(M8) -> 2T-C32BD1I-TG | C8: =IF(OR(N8="",N8=0),"",N8) -> HD-Ready,DVB-T2,Big sound 20W,Metal mesh design,USB movie | D8: =IFERROR(K8,"") -> 2020-02-01 | E8: =P8 -> 2435340 | F8: =IF(O8="DISC",1,0) -> 0 | G8: =IF(R8="","",R8) | I8: =IF(YEAR(O8)=2022,2000+DAY(O8),YEAR(O8)) -> 2020 | J8: =IF(MONTH(O8)<10,"0"&MONTH(O8),MONTH(O8)) -> 02 | K8: =I8&"-"&J8&"-01" -> 2020-02-01 | M8: 2T-C32BD1I-TG | N8: HD-Ready,DVB-T2,Big sound 20W,Metal mesh design,USB movie | O8: 43862 | P8: 2435340
A9: =VLOOKUP(LEFT(M9,3),Category!$G$3:$H$73,2,0) -> TELEVISION | B9: =UPPER(M9) -> 2T-C32BG1I | C9: =IF(OR(N9="",N9=0),"",N9) -> HD-ready, Android TV,Google assistant,Bluetooth audio out, azan reminder | D9: =IFERROR(K9,"") -> 2020-01-01 | E9: =P9 -> 3030300 | F9: =IF(O9="DISC",1,0) -> 0 | G9: =IF(R9="","",R9) | I9: =IF(YEAR(O9)=2022,2000+DAY(O9),YEAR(O9)) -> 2020 | J9: =IF(MONTH(O9)<10,"0"&MONTH(O9),MONTH(O9)) -> 01 | K9: =I9&"-"&J9&"-01" -> 2020-01-01 | M9: 2T-C32BG1I | N9: HD-ready, Android TV,Google assistant,Bluetooth audio out, azan reminder | O9: 43831 | P9: 3030300
A10: =VLOOKUP(LEFT(M10,3),Category!$G$3:$H$73,2,0) -> TELEVISION | B10: =UPPER(M10) -> 2T-C32DC1I | C10: =IF(OR(N10="",N10=0),"",N10) -> HD-Ready . DVB-T2 Ready,USB Music | D10: =IFERROR(K10,"") -> 2021-04-01 | E10: =P10 -> 2055720 | F10: =IF(O10="DISC",1,0) -> 0 | G10: =IF(R10="","",R10) | I10: =IF(YEAR(O10)=2022,2000+DAY(O10),YEAR(O10)) -> 2021 | J10: =IF(MONTH(O10)<10,"0"&MONTH(O10),MONTH(O10)) -> 04 | K10: =I10&"-"&J10&"-01" -> 2021-04-01 | M10: 2T-C32DC1I | N10: HD-Ready . DVB-T2 Ready,USB Music | O10: 44287 | P10: 2055720
A11: =VLOOKUP(LEFT(M11,3),Category!$G$3:$H$73,2,0) -> TELEVISION | B11: =UPPER(M11) -> 2T-C32DD1I | C11: =IF(OR(N11="",N11=0),"",N11) -> HD-Ready . DVB-T2 Ready,USB Movie | D11: =IFERROR(K11,"") -> 2021-04-01 | E11: =P11 -> 2080140 | F11: =IF(O11="DISC",1,0) -> 0 | G11: =IF(R11="","",R11) | I11: =IF(YEAR(O11)=2022,2000+DAY(O11),YEAR(O11)) -> 2021 | J11: =IF(MONTH(O11)<10,"0"&MONTH(O11),MONTH(O11)) -> 04 | K11: =I11&"-"&J11&"-01" -> 2021-04-01 | M11: 2T-C32DD1I | N11: HD-Ready . DVB-T2 Ready,USB Movie | O11: 44287 | P11: 2080140
A12: =VLOOKUP(LEFT(M12,3),Category!$G$3:$H$73,2,0) -> TELEVISION | B12: =UPPER(M12) -> 2T-C32DD1I-TT | C12: =IF(OR(N12="",N12=0),"",N12) -> HD-Ready . DVB-T2 Ready,USB Movie | D12: =IFERROR(K12,"") -> 2021-04-01 | E12: =P12 -> 2080140 | F12: =IF(O12="DISC",1,0) -> 0 | G12: =IF(R12="","",R12) | I12: =IF(YEAR(O12)=2022,2000+DAY(O12),YEAR(O12)) -> 2021 | J12: =IF(MONTH(O12)<10,"0"&MONTH(O12),MONTH(O12)) -> 04 | K12: =I12&"-"&J12&"-01" -> 2021-04-01 | M12: 2T-C32DD1I-TT | N12: HD-Ready . DVB-T2 Ready,USB Movie | O12: 44287 | P12: 2080140
A13: =VLOOKUP(LEFT(M13,3),Category!$G$3:$H$73,2,0) -> TELEVISION | B13: =UPPER(M13) -> 2T-C32DF1I | C13: =IF(OR(N13="",N13=0),"",N13) -> HD-Ready,HDR,New EasySmart,Netflix,Youtube,Apps Store,Game Mode,Mirroring | D13: =IFERROR(K13,"") -> 2001-01-01 | E13: =P13 -> 2850480 | F13: =IF(O13="DISC",1,0) -> 0 | G13: =IF(R13="","",R13) | I13: =IF(YEAR(O13)=2022,2000+DAY(O13),YEAR(O13)) -> 2001 | J13: =IF(MONTH(O13)<10,"0"&MONTH(O13),MONTH(O13)) -> 01 | K13: =I13&"-"&J13&"-01" -> 2001-01-01 | M13: 2T-C32DF1i | N13: HD-Ready,HDR,New EasySmart,Netflix,Youtube,Apps Store,Game Mode,Mirroring | O13: 44562 | P13: 2850480
A14: =VLOOKUP(LEFT(M14,3),Category!$G$3:$H$73,2,0) -> TELEVISION | B14: =UPPER(M14) -> 2T-C32EG1I | C14: =IF(OR(N14="",N14=0),"",N14) -> HD-Ready . Google TV . Kids Mode . Game Mode . Chromecast . Bluetooth Audio | D14: =IFERROR(K14,"") -> 2001-10-01 | E14: =P14 -> 3088020 | F14: =IF(O14="DISC",1,0) -> 0 | G14: =IF(R14="","",R14) | I14: =IF(YEAR(O14)=2022,2000+DAY(O14),YEAR(O14)) -> 2001 | J14: =IF(MONTH(O14)<10,"0"&MONTH(O14),MONTH(O14)) -> 10 | K14: =I14&"-"&J14&"-01" -> 2001-10-01 | M14: 2T-C32EG1I | N14: HD-Ready . Google TV . Kids Mode . Game Mode . Chromecast . Bluetooth Audio | O14: 44835 | P14: 3088020
A15: =VLOOKUP(LEFT(M15,3),Category!$G$3:$H$73,2,0) -> TELEVISION | B15: =UPPER(M15) -> 2T-C42BD1I | C15: =IF(OR(N15="",N15=0),"",N15) -> Full HD,DVB-T2,Child timer | D15: =IFERROR(K15,"") -> 2019-09-01 | E15: =P15 -> 3800640 | F15: =IF(O15="DISC",1,0) -> 0 | G15: =IF(R15="","",R15) | I15: =IF(YEAR(O15)=2022,2000+DAY(O15),YEAR(O15)) -> 2019 | J15: =IF(MONTH(O15)<10,"0"&MONTH(O15),MONTH(O15)) -> 09 | K15: =I15&"-"&J15&"-01" -> 2019-09-01 | M15: 2T-C42BD1I | N15: Full HD,DVB-T2,Child timer | O15: 43709 | P15: 3800640
A16: =VLOOKUP(LEFT(M16,3),Category!$G$3:$H$73,2,0) -> TELEVISION | B16: =UPPER(M16) -> 2T-C42BG1I | C16: =IF(OR(N16="",N16=0),"",N16) -> Full-HD, Android TV,Google assistant,Bluetooth audio out, azan reminder | D16: =IFERROR(K16,"") -> 2020-01-01 | E16: =P16 -> 4275720 | F16: =IF(O16="DISC",1,0) -> 0 | G16: =IF(R16="","",R16) | I16: =IF(YEAR(O16)=2022,2000+DAY(O16),YEAR(O16)) -> 2020 | J16: =IF(MONTH(O16)<10,"0"&MONTH(O16),MONTH(O16)) -> 01 | K16: =I16&"-"&J16&"-01" -> 2020-01-01 | M16: 2T-C42BG1I | N16: Full-HD, Android TV,Google assistant,Bluetooth audio out, azan reminder | O16: 43831 | P16: 4275720
... A150: =VLOOKUP(LEFT(M150,3),Category!$G$3:$H$73,2,0) -> AUDIO | B150: =UPPER(M150) -> CP-SW60A1 | C150: =IF(OR(N150="",N150=0),"",N150) -> Wireless bluetooth subwoofer | D150: =IFERROR(K150,"") -> 2018-10-01 | E150: =P150 -> 333000 | F150: =IF(O150="DISC",1,0) -> 0 | G150: =IF(R150="","",R150) | I150: =IF(YEAR(O150)=2022,2000+DAY(O150),YEAR(O150)) -> 2018 | J150: =IF(MONTH(O150)<10,"0"&MONTH(O150),MONTH(O150)) -> 10 | K150: =I150&"-"&J150&"-01" -> 2018-10-01 | M150: CP-SW60A1 | N150: Wireless bluetooth subwoofer | O150: 43374 | P150: 333000
A151: =VLOOKUP(LEFT(M151,3),Category!$G$3:$H$73,2,0) -> LED LIGHT | B151: =UPPER(M151) -> DL-0T13U | C151: =IF(OR(N151="",N151=0),"",N151) | D151: =IFERROR(K151,"") -> 1900-01-01 | E151: =P151 -> 293706 | F151: =IF(O151="DISC",1,0) -> 0 | G151: =IF(R151="","",R151) | I151: =IF(YEAR(O151)=2022,2000+DAY(O151),YEAR(O151)) -> 1900 | J151: =IF(MONTH(O151)<10,"0"&MONTH(O151),MONTH(O151)) -> 01 | K151: =I151&"-"&J151&"-01" -> 1900-01-01 | M151: DL-0T13U | N151: 0 | P151: 293706
A152: =VLOOKUP(LEFT(M152,3),Category!$G$3:$H$73,2,0) -> LED LIGHT | B152: =UPPER(M152) -> DL-0TC3U | C152: =IF(OR(N152="",N152=0),"",N152) | D152: =IFERROR(K152,"") -> 1900-01-01 | E152: =P152 -> 326007 | F152: =IF(O152="DISC",1,0) -> 0 | G152: =IF(R152="","",R152) | I152: =IF(YEAR(O152)=2022,2000+DAY(O152),YEAR(O152)) -> 1900 | J152: =IF(MONTH(O152)<10,"0"&MONTH(O152),MONTH(O152)) -> 01 | K152: =I152&"-"&J152&"-01" -> 1900-01-01 | M152: DL-0TC3U | N152: 0 | P152: 326007
A153: =VLOOKUP(LEFT(M153,3),Category!$G$3:$H$73,2,0) -> LED LIGHT | B153: =UPPER(M153) -> DL-T431NM | C153: =IF(OR(N153="",N153=0),"",N153) | D153: =IFERROR(K153,"") -> 1900-01-01 | E153: =P153 -> 260850 | F153: =IF(O153="DISC",1,0) -> 0 | G153: =IF(R153="","",R153) | I153: =IF(YEAR(O153)=2022,2000+DAY(O153),YEAR(O153)) -> 1900 | J153: =IF(MONTH(O153)<10,"0"&MONTH(O153),MONTH(O153)) -> 01 | K153: =I153&"-"&J153&"-01" -> 1900-01-01 | M153: DL-T431NM | N153: 0 | P153: 260850
A154: =VLOOKUP(LEFT(M154,3),Category!$G$3:$H$73,2,0) -> LED LIGHT | B154: =UPPER(M154) -> DL-YP046 | C154: =IF(OR(N154="",N154=0),"",N154) | D154: =IFERROR(K154,"") -> 1900-01-01 | E154: =P154 -> 229770 | F154: =IF(O154="DISC",1,0) -> 0 | G154: =IF(R154="","",R154) | I154: =IF(YEAR(O154)=2022,2000+DAY(O154),YEAR(O154)) -> 1900 | J154: =IF(MONTH(O154)<10,"0"&MONTH(O154),MONTH(O154)) -> 01 | K154: =I154&"-"&J154&"-01" -> 1900-01-01 | M154: DL-YP046 | N154: 0 | P154: 229770
A155: =VLOOKUP(LEFT(M155,3),Category!$G$3:$H$73,2,0) -> LED LIGHT | B155: =UPPER(M155) -> DN4A6XD474 | C155: =IF(OR(N155="",N155=0),"",N155) | D155: =IFERROR(K155,"") -> 2014-01-01 | E155: =P155 -> 144300 | F155: =IF(O155="DISC",1,0) -> 0 | G155: =IF(R155="","",R155) | I155: =IF(YEAR(O155)=2022,2000+DAY(O155),YEAR(O155)) -> 2014 | J155: =IF(MONTH(O155)<10,"0"&MONTH(O155),MONTH(O155)) -> 01 | K155: =I155&"-"&J155&"-01" -> 2014-01-01 | M155: DN4A6XD474 | N155: 0 | O155: 41653 | P155: 144300
A156: =VLOOKUP(LEFT(M156,3),Category!$G$3:$H$73,2,0) -> LED LIGHT | B156: =UPPER(M156) -> DN4A6XD475 | C156: =IF(OR(N156="",N156=0),"",N156) | D156: =IFERROR(K156,"") -> 1900-01-01 | E156: =P156 -> 177600 | F156: =IF(O156="DISC",1,0) -> 0 | G156: =IF(R156="","",R156) | I156: =IF(YEAR(O156)=2022,2000+DAY(O156),YEAR(O156)) -> 1900 | J156: =IF(MONTH(O156)<10,"0"&MONTH(O156),MONTH(O156)) -> 01 | K156: =I156&"-"&J156&"-01" -> 1900-01-01 | M156: DN4A6XD475 | N156: 0 | P156: 177600
A157: =VLOOKUP(LEFT(M157,3),Category!$G$3:$H$73,2,0) -> LED LIGHT | B157: =UPPER(M157) -> DN4A6XZ476 | C157: =IF(OR(N157="",N157=0),"",N157) | D157: =IFERROR(K157,"") -> 1900-01-01 | E157: =P157 -> 44400 | F157: =IF(O157="DISC",1,0) -> 0 | G157: =IF(R157="","",R157) | I157: =IF(YEAR(O157)=2022,2000+DAY(O157),YEAR(O157)) -> 1900 | J157: =IF(MONTH(O157)<10,"0"&MONTH(O157),MONTH(O157)) -> 01 | K157: =I157&"-"&J157&"-01" -> 1900-01-01 | M157: DN4A6XZ476 | N157: 0 | P157: 44400
A158: =VLOOKUP(LEFT(M158,3),Category!$G$3:$H$73,2,0) -> DEHUMIDIFIER | B158: =UPPER(M158) -> DW-D12A-W | C158: =IF(OR(N158="",N158=0),"",N158) -> High Density 7000, Dry Clothing Mode, Dehumidifying Capacity, Dehumidification Area, Auto Louver | D158: =IFERROR(K158,"") -> 2023-01-01 | E158: =P158 -> 3253410 | F158: =IF(O158="DISC",1,0) -> 0 | G158: =IF(R158="","",R158) | I158: =IF(YEAR(O158)=2022,2000+DAY(O158),YEAR(O158)) -> 2023 | J158: =IF(MONTH(O158)<10,"0"&MONTH(O158),MONTH(O158)) -> 01 | K158: =I158&"-"&J158&"-01" -> 2023-01-01 | M158: DW-D12A-W | N158: High Density 7000, Dry Clothing Mode, Dehumidifying Capacity, Dehumidification Area, Auto Louver | O158: 44927 | P158: 3253410
A159: =VLOOKUP(LEFT(M159,3),Category!$G$3:$H$73,2,0) -> DEHUMIDIFIER | B159: =UPPER(M159) -> DW-E16FA-W | C159: =IF(OR(N159="",N159=0),"",N159) -> High Density 7000, 2 IN 1, Dehumidifying Capacity, Dehumidification Area, Dry Clothing Mode | D159: =IFERROR(K159,"") -> 2023-01-01 | E159: =P159 -> 4689750 | F159: =IF(O159="DISC",1,0) -> 0 | G159: =IF(R159="","",R159) | I159: =IF(YEAR(O159)=2022,2000+DAY(O159),YEAR(O159)) -> 2023 | J159: =IF(MONTH(O159)<10,"0"&MONTH(O159),MONTH(O159)) -> 01 | K159: =I159&"-"&J159&"-01" -> 2023-01-01 | M159: DW-E16FA-W | N159: High Density 7000, 2 IN 1, Dehumidifying Capacity, Dehumidification Area, Dry Clothing Mode | O159: 44927 | P159: 4689750
A160: =VLOOKUP(LEFT(M160,3),Category!$G$3:$H$73,2,0) -> VACUUM CLEANER | B160: =UPPER(M160) -> EC-8305-B | C160: =IF(OR(N160="",N160=0),"",N160) -> 400 Watt, | D160: =IFERROR(K160,"") -> 2015-08-01 | E160: =P160 -> 890220 | F160: =IF(O160="DISC",1,0) -> 0 | G160: =IF(R160="","",R160) | I160: =IF(YEAR(O160)=2022,2000+DAY(O160),YEAR(O160)) -> 2015 | J160: =IF(MONTH(O160)<10,"0"&MONTH(O160),MONTH(O160)) -> 08 | K160: =I160&"-"&J160&"-01" -> 2015-08-01 | M160: EC-8305-B | N160: 400 Watt, | O160: 42217 | P160: 890220
A161: =VLOOKUP(LEFT(M161,3),Category!$G$3:$H$73,2,0) -> VACUUM CLEANER | B161: =UPPER(M161) -> EC-8305-P | C161: =IF(OR(N161="",N161=0),"",N161) -> Low Wattage 400 Watt | D161: =IFERROR(K161,"") -> 2015-08-01 | E161: =P161 -> 890220 | F161: =IF(O161="DISC",1,0) -> 0 | G161: =IF(R161="","",R161) | I161: =IF(YEAR(O161)=2022,2000+DAY(O161),YEAR(O161)) -> 2015 | J161: =IF(MONTH(O161)<10,"0"&MONTH(O161),MONTH(O161)) -> 08 | K161: =I161&"-"&J161&"-01" -> 2015-08-01 | M161: EC-8305-P | N161: Low Wattage 400 Watt | O161: 42217 | P161: 890220
A162: =VLOOKUP(LEFT(M162,3),Category!$G$3:$H$73,2,0) -> VACUUM CLEANER | B162: =UPPER(M162) -> EC-CW60 | C162: =IF(OR(N162="",N162=0),"",N162) -> Wet and Dry 600 Watt | D162: =IFERROR(K162,"") -> 2009-08-01 | E162: =P162 -> 922410 | F162: =IF(O162="DISC",1,0) -> 0 | G162: =IF(R162="","",R162) | I162: =IF(YEAR(O162)=2022,2000+DAY(O162),YEAR(O162)) -> 2009 | J162: =IF(MONTH(O162)<10,"0"&MONTH(O162),MONTH(O162)) -> 08 | K162: =I162&"-"&J162&"-01" -> 2009-08-01 | M162: EC-CW60 | N162: Wet and Dry 600 Watt | O162: 40026 | P162: 922410
A163: =VLOOKUP(LEFT(M163,3),Category!$G$3:$H$73,2,0) -> VACUUM CLEANER | B163: =UPPER(M163) -> EC-HX100Y-S | C163: =IF(OR(N163="",N163=0),"",N163) | D163: =IFERROR(K163,"") -> 2015-11-01 | E163: =P163 -> 2664000 | F163: =IF(O163="DISC",1,0) -> 0 | G163: =IF(R163="","",R163) | I163: =IF(YEAR(O163)=2022,2000+DAY(O163),YEAR(O163)) -> 2015 | J163: =IF(MONTH(O163)<10,"0"&MONTH(O163),MONTH(O163)) -> 11 | K163: =I163&"-"&J163&"-01" -> 2015-11-01 | M163: EC-HX100Y-S | N163: 0 | O163: 42309 | P163: 2664000
A164: =VLOOKUP(LEFT(M164,3),Category!$G$3:$H$73,2,0) -> VACUUM CLEANER | B164: =UPPER(M164) -> EC-NS18-BK | C164: =IF(OR(N164="",N164=0),"",N164) -> Bagless vacum cleaner,low wattage 450 watt, dry vacum cleaner, black colour | D164: =IFERROR(K164,"") -> 2017-11-01 | E164: =P164 -> 946830 | F164: =IF(O164="DISC",1,0) -> 0 | G164: =IF(R164="","",R164) | I164: =IF(YEAR(O164)=2022,2000+DAY(O164),YEAR(O164)) -> 2017 | J164: =IF(MONTH(O164)<10,"0"&MONTH(O164),MONTH(O164)) -> 11 | K164: =I164&"-"&J164&"-01" -> 2017-11-01 | M164: EC-NS18-BK | N164: Bagless vacum cleaner,low wattage 450 watt, dry vacum cleaner, black colour | O164: 43040 | P164: 946830
A165: =VLOOKUP(LEFT(M165,3),Category!$G$3:$H$73,2,0) -> VACUUM CLEANER | B165: =UPPER(M165) -> EC-NS18-RD | C165: =IF(OR(N165="",N165=0),"",N165) -> Bagless vacum cleaner,low wattage 450 watt, dry vacum cleaner, red colour | D165: =IFERROR(K165,"") -> 2017-11-01 | E165: =P165 -> 946830 | F165: =IF(O165="DISC",1,0) -> 0 | G165: =IF(R165="","",R165) | I165: =IF(YEAR(O165)=2022,2000+DAY(O165),YEAR(O165)) -> 2017 | J165: =IF(MONTH(O165)<10,"0"&MONTH(O165),MONTH(O165)) -> 11 | K165: =I165&"-"&J165&"-01" -> 2017-11-01 | M165: EC-NS18-RD | N165: Bagless vacum cleaner,low wattage 450 watt, dry vacum cleaner, red colour | O165: 43040 | P165: 946830
A166: =VLOOKUP(LEFT(M166,3),Category!$G$3:$H$73,2,0) -> VACUUM CLEANER | B166: =UPPER(M166) -> EC-SA95Y-R | C166: =IF(OR(N166="",N166=0),"",N166) -> Cordless vacuum cleaner with Mop Kit, Mopping System with water release, Detachable Battery Pack | D166: =IFERROR(K166,"") -> 2021-07-01 | E166: =P166 -> 2377620 | F166: =IF(O166="DISC",1,0) -> 0 | G166: =IF(R166="","",R166) | I166: =IF(YEAR(O166)=2022,2000+DAY(O166),YEAR(O166)) -> 2021 | J166: =IF(MONTH(O166)<10,"0"&MONTH(O166),MONTH(O166)) -> 07 | K166: =I166&"-"&J166&"-01" -> 2021-07-01 | M166: EC-SA95Y-R | N166: Cordless vacuum cleaner with Mop Kit, Mopping System with water release, Detachable Battery Pack | O166: 44378 | P166: 2377620
A167: =VLOOKUP(LEFT(M167,3),Category!$G$3:$H$73,2,0) -> SMALL HOME APPLIANCES | B167: =UPPER(M167) -> EI-N05-B | C167: =IF(OR(N167="",N167=0),"",N167) | D167: =IFERROR(K167,"") -> 2018-07-01 | E167: =P167 -> 189810 | F167: =IF(O167="DISC",1,0) -> 0 | G167: =IF(R167="","",R167) | I167: =IF(YEAR(O167)=2022,2000+DAY(O167),YEAR(O167)) -> 2018 | J167: =IF(MONTH(O167)<10,"0"&MONTH(O167),MONTH(O167)) -> 07 | K167: =I167&"-"&J167&"-01" -> 2018-07-01 | M167: EI-N05-B | N167: 0 | O167: 43282 | P167: 189810
A168: =VLOOKUP(LEFT(M168,3),Category!$G$3:$H$73,2,0) -> SMALL HOME APPLIANCES | B168: =UPPER(M168) -> EI-N05-P | C168: =IF(OR(N168="",N168=0),"",N168) | D168: =IFERROR(K168,"") -> 2018-07-01 | E168: =P168 -> 189810 | F168: =IF(O168="DISC",1,0) -> 0 | G168: =IF(R168="","",R168) | I168: =IF(YEAR(O168)=2022,2000+DAY(O168),YEAR(O168)) -> 2018 | J168: =IF(MONTH(O168)<10,"0"&MONTH(O168),MONTH(O168)) -> 07 | K168: =I168&"-"&J168&"-01" -> 2018-07-01 | M168: EI-N05-P | N168: 0 | O168: 43282 | P168: 189810
A169: =VLOOKUP(LEFT(M169,3),Category!$G$3:$H$73,2,0) -> SMALL HOME APPLIANCES | B169: =UPPER(M169) -> EI-N10-GY | C169: =IF(OR(N169="",N169=0),"",N169) -> Electric Iron (Dry), 350W | D169: =IFERROR(K169,"") -> 2001-11-01 | E169: =P169 -> 203130 | F169: =IF(O169="DISC",1,0) -> 0 | G169: =IF(R169="","",R169) | I169: =IF(YEAR(O169)=2022,2000+DAY(O169),YEAR(O169)) -> 2001 | J169: =IF(MONTH(O169)<10,"0"&MONTH(O169),MONTH(O169)) -> 11 | K169: =I169&"-"&J169&"-01" -> 2001-11-01 | M169: EI-N10-GY | N169: Electric Iron (Dry), 350W | O169: 44866 | P169: 203130
A170: =VLOOKUP(LEFT(M170,3),Category!$G$3:$H$73,2,0) -> SMALL HOME APPLIANCES | B170: =UPPER(M170) -> EI-N10-WH | C170: =IF(OR(N170="",N170=0),"",N170) -> Electric Iron (Dry), 350W | D170: =IFERROR(K170,"") -> 2001-11-01 | E170: =P170 -> 203130 | F170: =IF(O170="DISC",1,0) -> 0 | G170: =IF(R170="","",R170) | I170: =IF(YEAR(O170)=2022,2000+DAY(O170),YEAR(O170)) -> 2001 | J170: =IF(MONTH(O170)<10,"0"&MONTH(O170),MONTH(O170)) -> 11 | K170: =I170&"-"&J170&"-01" -> 2001-11-01 | M170: EI-N10-WH | N170: Electric Iron (Dry), 350W | O170: 44866 | P170: 203130
A171: =VLOOKUP(LEFT(M171,3),Category!$G$3:$H$73,2,0) -> SMALL HOME APPLIANCES | B171: =UPPER(M171) -> EJ-C20Y-RD | C171: =IF(OR(N171="",N171=0),"",N171) -> Slow juicer, power 150 W, Grinding technology | D171: =IFERROR(K171,"") -> 2017-02-01 | E171: =P171 -> 2170050 | F171: =IF(O171="DISC",1,0) -> 0 | G171: =IF(R171="","",R171) | I171: =IF(YEAR(O171)=2022,2000+DAY(O171),YEAR(O171)) -> 2017 | J171: =IF(MONTH(O171)<10,"0"&MONTH(O171),MONTH(O171)) -> 02 | K171: =I171&"-"&J171&"-01" -> 2017-02-01 | M171: EJ-C20Y-RD | N171: Slow juicer, power 150 W, Grinding technology | O171: 42767 | P171: 2170050
A172: =VLOOKUP(LEFT(M172,3),Category!$G$3:$H$73,2,0) -> SMALL HOME APPLIANCES | B172: =UPPER(M172) -> EKJ-156-BK | C172: =IF(OR(N172="",N172=0),"",N172) -> Auto lid opening function, Dry boil protection, On/off switch with indicator light, Capacity 1.5L | D172: =IFERROR(K172,"") -> 2018-05-01 | E172: =P172 -> 344100 | F172: =IF(O172="DISC",1,0) -> 0 | G172: =IF(R172="","",R172) | I172: =IF(YEAR(O172)=2022,2000+DAY(O172),YEAR(O172)) -> 2018 | J172: =IF(MONTH(O172)<10,"0"&MONTH(O172),MONTH(O172)) -> 05 | K172: =I172&"-"&J172&"-01" -> 2018-05-01 | M172: EKJ-156-BK | N172: Auto lid opening function, Dry boil protection, On/off switch with indicator light, Capacity 1.5L | O172: 43221 | P172: 344100
A173: =VLOOKUP(LEFT(M173,3),Category!$G$3:$H$73,2,0) -> SMALL HOME APPLIANCES | B173: =UPPER(M173) -> EKJ-177-BK | C173: =IF(OR(N173="",N173=0),"",N173) -> Kettle jug,Black colour,1.7 Liter,800 Watt,Double layer cool touch body | D173: =IFERROR(K173,"") -> 2020-12-01 | E173: =P173 -> 352980 | F173: =IF(O173="DISC",1,0) -> 0 | G173: =IF(R173="","",R173) | I173: =IF(YEAR(O173)=2022,2000+DAY(O173),YEAR(O173)) -> 2020 | J173: =IF(MONTH(O173)<10,"0"&MONTH(O173),MONTH(O173)) -> 12 | K173: =I173&"-"&J173&"-01" -> 2020-12-01 | M173: EKJ-177-BK | N173: Kettle jug,Black colour,1.7 Liter,800 Watt,Double layer cool touch body | O173: 44166 | P173: 352980
A174: =VLOOKUP(LEFT(M174,3),Category!$G$3:$H$73,2,0) -> SMALL HOME APPLIANCES | B174: =UPPER(M174) -> EKJ-177-WH | C174: =IF(OR(N174="",N174=0),"",N174) -> Kettle jug,White colour,1.7 Liter,800 Watt,Double layer cool touch body | D174: =IFERROR(K174,"") -> 2020-12-01 | E174: =P174 -> 352980 | F174: =IF(O174="DISC",1,0) -> 0 | G174: =IF(R174="","",R174) | I174: =IF(YEAR(O174)=2022,2000+DAY(O174),YEAR(O174)) -> 2020 | J174: =IF(MONTH(O174)<10,"0"&MONTH(O174),MONTH(O174)) -> 12 | K174: =I174&"-"&J174&"-01" -> 2020-12-01 | M174: EKJ-177-WH | N174: Kettle jug,White colour,1.7 Liter,800 Watt,Double layer cool touch body | O174: 44166 | P174: 352980
...

Sheet Category
B2: MODEL | C2: BEGINNING | D2: CATEGORY | G2: BEGINNING | H2: CATEGORY
B3: 2T-C24CB3I-BK | C3: =LEFT(B3,3) -> 2T- | D3: TELEVISION | G3: 2T- | H3: TELEVISION
B4: 2T-C24DC1I | C4: =LEFT(B4,3) -> 2T- | D4: TELEVISION | G4: 4T- | H4: TELEVISION
B5: 2T-C24DD1I | C5: =LEFT(B5,3) -> 2T- | D5: TELEVISION | G5: 8T- | H5: TELEVISION
B6: 2T-C24DD1I-TT | C6: =LEFT(B6,3) -> 2T- | D6: TELEVISION | G6: AH- | H6: AIR CONDITIONER
B7: 2T-C32BB1I-TB | C7: =LEFT(B7,3) -> 2T- | D7: TELEVISION | G7: AN- | H7: AUDIO
B8: 2T-C32BD1I-TG | C8: =LEFT(B8,3) -> 2T- | D8: TELEVISION | G8: AX- | H8: HEALSIO WATER OVEN
B9: 2T-C32BG1I | C9: =LEFT(B9,3) -> 2T- | D9: TELEVISION | G9: BC- | H9: BICYCLE
B10: 2T-C32DC1I | C10: =LEFT(B10,3) -> 2T- | D10: TELEVISION | G10: CBO | H10: AUDIO
B11: 2T-C32DD1I | C11: =LEFT(B11,3) -> 2T- | D11: TELEVISION | G11: CP- | H11: AUDIO
B12: 2T-C32DD1I-TT | C12: =LEFT(B12,3) -> 2T- | D12: TELEVISION | G12: CV- | H12: AIR CONDITIONER
B13: 2T-C32DF1i | C13: =LEFT(B13,3) -> 2T- | D13: TELEVISION | G13: DL- | H13: LED LIGHT
B14: 2T-C42BB1I | C14: =LEFT(B14,3) -> 2T- | D14: TELEVISION | G14: DN4 | H14: LED LIGHT
... B73: AH-XP10UHY | C73: =LEFT(B73,3) -> AH- | D73: AIR CONDITIONER | G73: SWD | H73: WATER DISPENSER
B74: AH-XP10VXY | C74: =LEFT(B74,3) -> AH- | D74: AIR CONDITIONER
B75: AH-XP10YHY | C75: =LEFT(B75,3) -> AH- | D75: AIR CONDITIONER
B76: AH-XP13VXY | C76: =LEFT(B76,3) -> AH- | D76: AIR CONDITIONER
B77: AH-XP13YHY | C77: =LEFT(B77,3) -> AH- | D77: AIR CONDITIONER
B78: AH-XP6UHY | C78: =LEFT(B78,3) -> AH- | D78: AIR CONDITIONER
B79: AH-XP6YHY | C79: =LEFT(B79,3) -> AH- | D79: AIR CONDITIONER
B80: AN-SS2(BK) | C80: =LEFT(B80,3) -> AN- | D80: AUDIO
B81: AN-SS2(WH) | C81: =LEFT(B81,3) -> AN- | D81: AUDIO
B82: AN-SS2M(BK) | C82: =LEFT(B82,3) -> AN- | D82: AUDIO
B83: AN-SS2M(WH) | C83: =LEFT(B83,3) -> AN- | D83: AUDIO
B84: AX-1500IN(R) | C84: =LEFT(B84,3) -> AX- | D84: HEALSIO WATER OVEN
B85: AX-1700IN(R) | C85: =LEFT(B85,3) -> AX- | D85: HEALSIO WATER OVEN
... B526: SWD-88EHL-SL | C526: =LEFT(B526,3) -> SWD | D526: WATER DISPENSER
