Workbook

Sheet Upload Format
A1: RANGKUMAN HASIL WEB SURVEY (CS SURVEY BY WEB) | N1: COPY PASTE VALUE HERE | Q1: DATA ON THOSE COLUMN WILL BE UPLOADED
A3: No | B3: FU type | C3: Notif / Job Order | D3: Q1 point | E3: Q1 remark | F3: Q2 point | G3: Q2 remark | H3: Q3 point | I3: Q3 remark | J3: Q4 point | K3: Datetime submission | N3: No | O3: FU type | P3: Notif / Job Order | Q3: Q1 point | R3: Q1 remark | S3: Q2 point | T3: Q2 remark | U3: Q3 point | V3: Q3 remark | W3: Q4 point | X3: Datetime submission
A4: =IF(B4="","",ROW()-COUNTBLANK($B$4:B4)-3) -> 1 | B4: ='web survey'!C2 -> FU-ACInstall | C4: ='web survey'!AA2 -> TBS13A2400330 | D4: =IF(B4="FU-ACInstall",VLOOKUP(VALUE('web survey'!D2),ref!$B$6:$C$7,2,0)&" ("&'web survey'!D2&")",VLOOKUP(VALUE('web survey'!D2),ref!$E$6:$F$10,2,0)&" ("&'web survey'!D2&")") -> Yes, There is installation (10) | E4: ='web survey'!S2 | F4: =IF(B4="FU-ACInstall",VLOOKUP(VALUE('web survey'!E2),ref!$B$10:$C$12,2,0)&" ("&'web survey'!E2&")",VLOOKUP(VALUE('web survey'!E2),ref!$E$13:$F$17,2,0)&" ("&'web survey'!E2&")") -> Good (10) | G4: ='web survey'!T2 | H4: =IF(B4="FU-ACInstall",VLOOKUP(VALUE('web survey'!F2),ref!$B$15:$C$17,2,0)&" ("&'web survey'!F2&")",VLOOKUP(VALUE('web survey'!F2),ref!$E$20:$F$21,2,0)&" ("&'web survey'!F2&")") -> Good (10) | I4: ='web survey'!U2 | J4: =IF(B4="FU-ACInstall","-",VLOOKUP(VALUE('web survey'!G2),ref!$E$24:$F$26,2,0)&" ("&'web survey'!G2&")") -> - | K4: =YEAR('web survey'!Z2)&"-"&IF(MONTH('web survey'!Z2)<10,"0"&MONTH('web survey'!Z2),MONTH('web survey'!Z2))&"-"&IF(DAY('web survey'!Z2)<10,"0"&DAY('web survey'!Z2),DAY('web survey'!Z2))&" "&IF(HOUR('web survey'!Z2)<10,"0"&HOUR('web survey'!Z2),HOUR('web survey'!Z2))&":"&IF(MINUTE('web survey'!Z2)<10,"0"&MINUTE('web survey'!Z2),MINUTE('web survey'!Z2))&(":00'") -> 2024-08-21 16:53:00' | N4: 1 | O4: FU-ACInstall | P4: TBS13A2400330 | Q4: Yes, There is installation (10) | S4: Good (10) | U4: Good (10) | W4: - | X4: 21 Aug 2024 16:53
A5: =IF(B5="","",ROW()-COUNTBLANK($B$4:B5)-3) -> 2 | B5: ='web survey'!C3 -> FU-ACInstall | C5: ='web survey'!AA3 -> TBS13A2400333 | D5: =IF(B5="FU-ACInstall",VLOOKUP(VALUE('web survey'!D3),ref!$B$6:$C$7,2,0)&" ("&'web survey'!D3&")",VLOOKUP(VALUE('web survey'!D3),ref!$E$6:$F$10,2,0)&" ("&'web survey'!D3&")") -> Yes, There is installation (10) | E5: ='web survey'!S3 | F5: =IF(B5="FU-ACInstall",VLOOKUP(VALUE('web survey'!E3),ref!$B$10:$C$12,2,0)&" ("&'web survey'!E3&")",VLOOKUP(VALUE('web survey'!E3),ref!$E$13:$F$17,2,0)&" ("&'web survey'!E3&")") -> Good (10) | G5: ='web survey'!T3 | H5: =IF(B5="FU-ACInstall",VLOOKUP(VALUE('web survey'!F3),ref!$B$15:$C$17,2,0)&" ("&'web survey'!F3&")",VLOOKUP(VALUE('web survey'!F3),ref!$E$20:$F$21,2,0)&" ("&'web survey'!F3&")") -> Good (10) | I5: ='web survey'!U3 | J5: =IF(B5="FU-ACInstall","-",VLOOKUP(VALUE('web survey'!G3),ref!$E$24:$F$26,2,0)&" ("&'web survey'!G3&")") -> - | K5: =YEAR('web survey'!Z3)&"-"&IF(MONTH('web survey'!Z3)<10,"0"&MONTH('web survey'!Z3),MONTH('web survey'!Z3))&"-"&IF(DAY('web survey'!Z3)<10,"0"&DAY('web survey'!Z3),DAY('web survey'!Z3))&" "&IF(HOUR('web survey'!Z3)<10,"0"&HOUR('web survey'!Z3),HOUR('web survey'!Z3))&":"&IF(MINUTE('web survey'!Z3)<10,"0"&MINUTE('web survey'!Z3),MINUTE('web survey'!Z3))&(":00'") -> 2024-08-21 15:43:00' | N5: 2 | O5: FU-ACInstall | P5: TBS13A2400333 | Q5: Yes, There is installation (10) | S5: Good (10) | U5: Good (10) | W5: - | X5: 21 Aug 2024 15:43
A6: =IF(B6="","",ROW()-COUNTBLANK($B$4:B6)-3) -> 3 | B6: ='web survey'!C4 -> FU-ACInstall | C6: ='web survey'!AA4 -> EMT19A2400123 | D6: =IF(B6="FU-ACInstall",VLOOKUP(VALUE('web survey'!D4),ref!$B$6:$C$7,2,0)&" ("&'web survey'!D4&")",VLOOKUP(VALUE('web survey'!D4),ref!$E$6:$F$10,2,0)&" ("&'web survey'!D4&")") -> No installation from SHARP (-10) | E6: ='web survey'!S4 | F6: =IF(B6="FU-ACInstall",VLOOKUP(VALUE('web survey'!E4),ref!$B$10:$C$12,2,0)&" ("&'web survey'!E4&")",VLOOKUP(VALUE('web survey'!E4),ref!$E$13:$F$17,2,0)&" ("&'web survey'!E4&")") -> Spec Under Expectation (5) | G6: ='web survey'!T4 | H6: =IF(B6="FU-ACInstall",VLOOKUP(VALUE('web survey'!F4),ref!$B$15:$C$17,2,0)&" ("&'web survey'!F4&")",VLOOKUP(VALUE('web survey'!F4),ref!$E$20:$F$21,2,0)&" ("&'web survey'!F4&")") -> Poor (-10) | I6: ='web survey'!U4 | J6: =IF(B6="FU-ACInstall","-",VLOOKUP(VALUE('web survey'!G4),ref!$E$24:$F$26,2,0)&" ("&'web survey'!G4&")") -> - | K6: =YEAR('web survey'!Z4)&"-"&IF(MONTH('web survey'!Z4)<10,"0"&MONTH('web survey'!Z4),MONTH('web survey'!Z4))&"-"&IF(DAY('web survey'!Z4)<10,"0"&DAY('web survey'!Z4),DAY('web survey'!Z4))&" "&IF(HOUR('web survey'!Z4)<10,"0"&HOUR('web survey'!Z4),HOUR('web survey'!Z4))&":"&IF(MINUTE('web survey'!Z4)<10,"0"&MINUTE('web survey'!Z4),MINUTE('web survey'!Z4))&(":00'") -> 2024-08-21 15:30:00' | N6: 3 | O6: FU-ACInstall | P6: EMT19A2400123 | Q6: No installation from SHARP (-10) | S6: Spec Under Expectation (5) | U6: Poor (-10) | W6: - | X6: 21 Aug 2024 15:30
A7: =IF(B7="","",ROW()-COUNTBLANK($B$4:B7)-3) -> 4 | B7: ='web survey'!C5 -> FU-ACInstall | C7: ='web survey'!AA5 -> TBS13A2400337 | D7: =IF(B7="FU-ACInstall",VLOOKUP(VALUE('web survey'!D5),ref!$B$6:$C$7,2,0)&" ("&'web survey'!D5&")",VLOOKUP(VALUE('web survey'!D5),ref!$E$6:$F$10,2,0)&" ("&'web survey'!D5&")") -> Yes, There is installation (10) | E7: ='web survey'!S5 | F7: =IF(B7="FU-ACInstall",VLOOKUP(VALUE('web survey'!E5),ref!$B$10:$C$12,2,0)&" ("&'web survey'!E5&")",VLOOKUP(VALUE('web survey'!E5),ref!$E$13:$F$17,2,0)&" ("&'web survey'!E5&")") -> Good (10) | G7: ='web survey'!T5 | H7: =IF(B7="FU-ACInstall",VLOOKUP(VALUE('web survey'!F5),ref!$B$15:$C$17,2,0)&" ("&'web survey'!F5&")",VLOOKUP(VALUE('web survey'!F5),ref!$E$20:$F$21,2,0)&" ("&'web survey'!F5&")") -> Good (10) | I7: ='web survey'!U5 | J7: =IF(B7="FU-ACInstall","-",VLOOKUP(VALUE('web survey'!G5),ref!$E$24:$F$26,2,0)&" ("&'web survey'!G5&")") -> - | K7: =YEAR('web survey'!Z5)&"-"&IF(MONTH('web survey'!Z5)<10,"0"&MONTH('web survey'!Z5),MONTH('web survey'!Z5))&"-"&IF(DAY('web survey'!Z5)<10,"0"&DAY('web survey'!Z5),DAY('web survey'!Z5))&" "&IF(HOUR('web survey'!Z5)<10,"0"&HOUR('web survey'!Z5),HOUR('web survey'!Z5))&":"&IF(MINUTE('web survey'!Z5)<10,"0"&MINUTE('web survey'!Z5),MINUTE('web survey'!Z5))&(":00'") -> 2024-08-21 15:13:00' | N7: 4 | O7: FU-ACInstall | P7: TBS13A2400337 | Q7: Yes, There is installation (10) | S7: Good (10) | U7: Good (10) | W7: - | X7: 21 Aug 2024 15:13
A8: =IF(B8="","",ROW()-COUNTBLANK($B$4:B8)-3) -> 5 | B8: ='web survey'!C6 -> FU-Z1-Eng | C8: ='web survey'!AA6 -> 100891867 | D8: =IF(B8="FU-ACInstall",VLOOKUP(VALUE('web survey'!D6),ref!$B$6:$C$7,2,0)&" ("&'web survey'!D6&")",VLOOKUP(VALUE('web survey'!D6),ref!$E$6:$F$10,2,0)&" ("&'web survey'!D6&")") -> Good (10) | E8: ='web survey'!S6 | F8: =IF(B8="FU-ACInstall",VLOOKUP(VALUE('web survey'!E6),ref!$B$10:$C$12,2,0)&" ("&'web survey'!E6&")",VLOOKUP(VALUE('web survey'!E6),ref!$E$13:$F$17,2,0)&" ("&'web survey'!E6&")") -> Good (5) | G8: ='web survey'!T6 | H8: =IF(B8="FU-ACInstall",VLOOKUP(VALUE('web survey'!F6),ref!$B$15:$C$17,2,0)&" ("&'web survey'!F6&")",VLOOKUP(VALUE('web survey'!F6),ref!$E$20:$F$21,2,0)&" ("&'web survey'!F6&")") -> Different with SAP (-10) | I8: ='web survey'!U6 | J8: =IF(B8="FU-ACInstall","-",VLOOKUP(VALUE('web survey'!G6),ref!$E$24:$F$26,2,0)&" ("&'web survey'!G6&")") -> Jelas (5) | K8: =YEAR('web survey'!Z6)&"-"&IF(MONTH('web survey'!Z6)<10,"0"&MONTH('web survey'!Z6),MONTH('web survey'!Z6))&"-"&IF(DAY('web survey'!Z6)<10,"0"&DAY('web survey'!Z6),DAY('web survey'!Z6))&" "&IF(HOUR('web survey'!Z6)<10,"0"&HOUR('web survey'!Z6),HOUR('web survey'!Z6))&":"&IF(MINUTE('web survey'!Z6)<10,"0"&MINUTE('web survey'!Z6),MINUTE('web survey'!Z6))&(":00'") -> 2024-08-21 22:51:00' | N8: 5 | O8: FU-Z1-Eng | P8: 100891867 | Q8: Good (10) | S8: Good (5) | U8: Different with SAP (-10) | W8: Jelas (5) | X8: 21 Aug 2024 22:51
A9: =IF(B9="","",ROW()-COUNTBLANK($B$4:B9)-3) -> 6 | B9: ='web survey'!C7 -> FU-Z1-Eng | C9: ='web survey'!AA7 -> 203906108 | D9: =IF(B9="FU-ACInstall",VLOOKUP(VALUE('web survey'!D7),ref!$B$6:$C$7,2,0)&" ("&'web survey'!D7&")",VLOOKUP(VALUE('web survey'!D7),ref!$E$6:$F$10,2,0)&" ("&'web survey'!D7&")") -> Not Good (-10) | E9: ='web survey'!S7 | F9: =IF(B9="FU-ACInstall",VLOOKUP(VALUE('web survey'!E7),ref!$B$10:$C$12,2,0)&" ("&'web survey'!E7&")",VLOOKUP(VALUE('web survey'!E7),ref!$E$13:$F$17,2,0)&" ("&'web survey'!E7&")") -> Very Good (10) | G9: ='web survey'!T7 | H9: =IF(B9="FU-ACInstall",VLOOKUP(VALUE('web survey'!F7),ref!$B$15:$C$17,2,0)&" ("&'web survey'!F7&")",VLOOKUP(VALUE('web survey'!F7),ref!$E$20:$F$21,2,0)&" ("&'web survey'!F7&")") -> Appropriate with SAP / in Warranty (10) | I9: ='web survey'!U7 | J9: =IF(B9="FU-ACInstall","-",VLOOKUP(VALUE('web survey'!G7),ref!$E$24:$F$26,2,0)&" ("&'web survey'!G7&")") -> Jelas (5) | K9: =YEAR('web survey'!Z7)&"-"&IF(MONTH('web survey'!Z7)<10,"0"&MONTH('web survey'!Z7),MONTH('web survey'!Z7))&"-"&IF(DAY('web survey'!Z7)<10,"0"&DAY('web survey'!Z7),DAY('web survey'!Z7))&" "&IF(HOUR('web survey'!Z7)<10,"0"&HOUR('web survey'!Z7),HOUR('web survey'!Z7))&":"&IF(MINUTE('web survey'!Z7)<10,"0"&MINUTE('web survey'!Z7),MINUTE('web survey'!Z7))&(":00'") -> 2024-08-21 22:08:00' | N9: 6 | O9: FU-Z1-Eng | P9: 203906108 | Q9: Not Good (-10) | S9: Very Good (10) | U9: Appropriate with SAP / in Warranty (10) | W9: Jelas (5) | X9: 21 Aug 2024 22:08
A10: =IF(B10="","",ROW()-COUNTBLANK($B$4:B10)-3) -> 7 | B10: ='web survey'!C8 -> FU-Z1-Eng | C10: ='web survey'!AA8 -> 203909527 | D10: =IF(B10="FU-ACInstall",VLOOKUP(VALUE('web survey'!D8),ref!$B$6:$C$7,2,0)&" ("&'web survey'!D8&")",VLOOKUP(VALUE('web survey'!D8),ref!$E$6:$F$10,2,0)&" ("&'web survey'!D8&")") -> Good (10) | E10: ='web survey'!S8 | F10: =IF(B10="FU-ACInstall",VLOOKUP(VALUE('web survey'!E8),ref!$B$10:$C$12,2,0)&" ("&'web survey'!E8&")",VLOOKUP(VALUE('web survey'!E8),ref!$E$13:$F$17,2,0)&" ("&'web survey'!E8&")") -> Very Good (10) | G10: ='web survey'!T8 | H10: =IF(B10="FU-ACInstall",VLOOKUP(VALUE('web survey'!F8),ref!$B$15:$C$17,2,0)&" ("&'web survey'!F8&")",VLOOKUP(VALUE('web survey'!F8),ref!$E$20:$F$21,2,0)&" ("&'web survey'!F8&")") -> Appropriate with SAP / in Warranty (10) | I10: ='web survey'!U8 | J10: =IF(B10="FU-ACInstall","-",VLOOKUP(VALUE('web survey'!G8),ref!$E$24:$F$26,2,0)&" ("&'web survey'!G8&")") -> Jelas (5) | K10: =YEAR('web survey'!Z8)&"-"&IF(MONTH('web survey'!Z8)<10,"0"&MONTH('web survey'!Z8),MONTH('web survey'!Z8))&"-"&IF(DAY('web survey'!Z8)<10,"0"&DAY('web survey'!Z8),DAY('web survey'!Z8))&" "&IF(HOUR('web survey'!Z8)<10,"0"&HOUR('web survey'!Z8),HOUR('web survey'!Z8))&":"&IF(MINUTE('web survey'!Z8)<10,"0"&MINUTE('web survey'!Z8),MINUTE('web survey'!Z8))&(":00'") -> 2024-08-21 20:35:00' | N10: 7 | O10: FU-Z1-Eng | P10: 203909527 | Q10: Good (10) | S10: Very Good (10) | U10: Appropriate with SAP / in Warranty (10) | W10: Jelas (5) | X10: 21 Aug 2024 20:35
A11: =IF(B11="","",ROW()-COUNTBLANK($B$4:B11)-3) -> 8 | B11: ='web survey'!C9 -> FU-Z1-Eng | C11: ='web survey'!AA9 -> 100892750 | D11: =IF(B11="FU-ACInstall",VLOOKUP(VALUE('web survey'!D9),ref!$B$6:$C$7,2,0)&" ("&'web survey'!D9&")",VLOOKUP(VALUE('web survey'!D9),ref!$E$6:$F$10,2,0)&" ("&'web survey'!D9&")") -> Good (10) | E11: ='web survey'!S9 | F11: =IF(B11="FU-ACInstall",VLOOKUP(VALUE('web survey'!E9),ref!$B$10:$C$12,2,0)&" ("&'web survey'!E9&")",VLOOKUP(VALUE('web survey'!E9),ref!$E$13:$F$17,2,0)&" ("&'web survey'!E9&")") -> Very Good (10) | G11: ='web survey'!T9 | H11: =IF(B11="FU-ACInstall",VLOOKUP(VALUE('web survey'!F9),ref!$B$15:$C$17,2,0)&" ("&'web survey'!F9&")",VLOOKUP(VALUE('web survey'!F9),ref!$E$20:$F$21,2,0)&" ("&'web survey'!F9&")") -> Appropriate with SAP / in Warranty (10) | I11: ='web survey'!U9 | J11: =IF(B11="FU-ACInstall","-",VLOOKUP(VALUE('web survey'!G9),ref!$E$24:$F$26,2,0)&" ("&'web survey'!G9&")") -> Jelas (5) | K11: =YEAR('web survey'!Z9)&"-"&IF(MONTH('web survey'!Z9)<10,"0"&MONTH('web survey'!Z9),MONTH('web survey'!Z9))&"-"&IF(DAY('web survey'!Z9)<10,"0"&DAY('web survey'!Z9),DAY('web survey'!Z9))&" "&IF(HOUR('web survey'!Z9)<10,"0"&HOUR('web survey'!Z9),HOUR('web survey'!Z9))&":"&IF(MINUTE('web survey'!Z9)<10,"0"&MINUTE('web survey'!Z9),MINUTE('web survey'!Z9))&(":00'") -> 2024-08-21 20:34:00' | N11: 8 | O11: FU-Z1-Eng | P11: 100892750 | Q11: Good (10) | S11: Very Good (10) | U11: Appropriate with SAP / in Warranty (10) | W11: Jelas (5) | X11: 21 Aug 2024 20:34
A12: =IF(B12="","",ROW()-COUNTBLANK($B$4:B12)-3) -> 9 | B12: ='web survey'!C10 -> FU-Z1-Eng | C12: ='web survey'!AA10 -> 203909674 | D12: =IF(B12="FU-ACInstall",VLOOKUP(VALUE('web survey'!D10),ref!$B$6:$C$7,2,0)&" ("&'web survey'!D10&")",VLOOKUP(VALUE('web survey'!D10),ref!$E$6:$F$10,2,0)&" ("&'web survey'!D10&")") -> Good (10) | E12: ='web survey'!S10 | F12: =IF(B12="FU-ACInstall",VLOOKUP(VALUE('web survey'!E10),ref!$B$10:$C$12,2,0)&" ("&'web survey'!E10&")",VLOOKUP(VALUE('web survey'!E10),ref!$E$13:$F$17,2,0)&" ("&'web survey'!E10&")") -> Very Good (10) | G12: ='web survey'!T10 | H12: =IF(B12="FU-ACInstall",VLOOKUP(VALUE('web survey'!F10),ref!$B$15:$C$17,2,0)&" ("&'web survey'!F10&")",VLOOKUP(VALUE('web survey'!F10),ref!$E$20:$F$21,2,0)&" ("&'web survey'!F10&")") -> Appropriate with SAP / in Warranty (10) | I12: ='web survey'!U10 | J12: =IF(B12="FU-ACInstall","-",VLOOKUP(VALUE('web survey'!G10),ref!$E$24:$F$26,2,0)&" ("&'web survey'!G10&")") -> Jelas (5) | K12: =YEAR('web survey'!Z10)&"-"&IF(MONTH('web survey'!Z10)<10,"0"&MONTH('web survey'!Z10),MONTH('web survey'!Z10))&"-"&IF(DAY('web survey'!Z10)<10,"0"&DAY('web survey'!Z10),DAY('web survey'!Z10))&" "&IF(HOUR('web survey'!Z10)<10,"0"&HOUR('web survey'!Z10),HOUR('web survey'!Z10))&":"&IF(MINUTE('web survey'!Z10)<10,"0"&MINUTE('web survey'!Z10),MINUTE('web survey'!Z10))&(":00'") -> 2024-08-21 19:49:00' | N12: 9 | O12: FU-Z1-Eng | P12: 203909674 | Q12: Good (10) | S12: Very Good (10) | U12: Appropriate with SAP / in Warranty (10) | W12: Jelas (5) | X12: 21 Aug 2024 19:49
A13: =IF(B13="","",ROW()-COUNTBLANK($B$4:B13)-3) -> 10 | B13: ='web survey'!C11 -> FU-Z1-Eng | C13: ='web survey'!AA11 -> 100893725 | D13: =IF(B13="FU-ACInstall",VLOOKUP(VALUE('web survey'!D11),ref!$B$6:$C$7,2,0)&" ("&'web survey'!D11&")",VLOOKUP(VALUE('web survey'!D11),ref!$E$6:$F$10,2,0)&" ("&'web survey'!D11&")") -> Good (10) | E13: ='web survey'!S11 | F13: =IF(B13="FU-ACInstall",VLOOKUP(VALUE('web survey'!E11),ref!$B$10:$C$12,2,0)&" ("&'web survey'!E11&")",VLOOKUP(VALUE('web survey'!E11),ref!$E$13:$F$17,2,0)&" ("&'web survey'!E11&")") -> Good (5) | G13: ='web survey'!T11 | H13: =IF(B13="FU-ACInstall",VLOOKUP(VALUE('web survey'!F11),ref!$B$15:$C$17,2,0)&" ("&'web survey'!F11&")",VLOOKUP(VALUE('web survey'!F11),ref!$E$20:$F$21,2,0)&" ("&'web survey'!F11&")") -> Appropriate with SAP / in Warranty (10) | I13: ='web survey'!U11 | J13: =IF(B13="FU-ACInstall","-",VLOOKUP(VALUE('web survey'!G11),ref!$E$24:$F$26,2,0)&" ("&'web survey'!G11&")") -> Jelas (5) | K13: =YEAR('web survey'!Z11)&"-"&IF(MONTH('web survey'!Z11)<10,"0"&MONTH('web survey'!Z11),MONTH('web survey'!Z11))&"-"&IF(DAY('web survey'!Z11)<10,"0"&DAY('web survey'!Z11),DAY('web survey'!Z11))&" "&IF(HOUR('web survey'!Z11)<10,"0"&HOUR('web survey'!Z11),HOUR('web survey'!Z11))&":"&IF(MINUTE('web survey'!Z11)<10,"0"&MINUTE('web survey'!Z11),MINUTE('web survey'!Z11))&(":00'") -> 2024-08-21 19:45:00' | N13: 10 | O13: FU-Z1-Eng | P13: 100893725 | Q13: Good (10) | S13: Good (5) | U13: Appropriate with SAP / in Warranty (10) | W13: Jelas (5) | X13: 21 Aug 2024 19:45
A14: =IF(B14="","",ROW()-COUNTBLANK($B$4:B14)-3) -> 11 | B14: ='web survey'!C12 -> FU-Z1-Eng | C14: ='web survey'!AA12 -> 203906953 | D14: =IF(B14="FU-ACInstall",VLOOKUP(VALUE('web survey'!D12),ref!$B$6:$C$7,2,0)&" ("&'web survey'!D12&")",VLOOKUP(VALUE('web survey'!D12),ref!$E$6:$F$10,2,0)&" ("&'web survey'!D12&")") -> Good (10) | E14: ='web survey'!S12 | F14: =IF(B14="FU-ACInstall",VLOOKUP(VALUE('web survey'!E12),ref!$B$10:$C$12,2,0)&" ("&'web survey'!E12&")",VLOOKUP(VALUE('web survey'!E12),ref!$E$13:$F$17,2,0)&" ("&'web survey'!E12&")") -> Very Good (10) | G14: ='web survey'!T12 | H14: =IF(B14="FU-ACInstall",VLOOKUP(VALUE('web survey'!F12),ref!$B$15:$C$17,2,0)&" ("&'web survey'!F12&")",VLOOKUP(VALUE('web survey'!F12),ref!$E$20:$F$21,2,0)&" ("&'web survey'!F12&")") -> Appropriate with SAP / in Warranty (10) | I14: ='web survey'!U12 | J14: =IF(B14="FU-ACInstall","-",VLOOKUP(VALUE('web survey'!G12),ref!$E$24:$F$26,2,0)&" ("&'web survey'!G12&")") -> Jelas (5) | K14: =YEAR('web survey'!Z12)&"-"&IF(MONTH('web survey'!Z12)<10,"0"&MONTH('web survey'!Z12),MONTH('web survey'!Z12))&"-"&IF(DAY('web survey'!Z12)<10,"0"&DAY('web survey'!Z12),DAY('web survey'!Z12))&" "&IF(HOUR('web survey'!Z12)<10,"0"&HOUR('web survey'!Z12),HOUR('web survey'!Z12))&":"&IF(MINUTE('web survey'!Z12)<10,"0"&MINUTE('web survey'!Z12),MINUTE('web survey'!Z12))&(":00'") -> 2024-08-21 19:03:00' | N14: 11 | O14: FU-Z1-Eng | P14: 203906953 | Q14: Good (10) | S14: Very Good (10) | U14: Appropriate with SAP / in Warranty (10) | W14: Jelas (5) | X14: 21 Aug 2024 19:03
A15: =IF(B15="","",ROW()-COUNTBLANK($B$4:B15)-3) -> 12 | B15: ='web survey'!C13 -> FU-Z1-Eng | C15: ='web survey'!AA13 -> 100892571 | D15: =IF(B15="FU-ACInstall",VLOOKUP(VALUE('web survey'!D13),ref!$B$6:$C$7,2,0)&" ("&'web survey'!D13&")",VLOOKUP(VALUE('web survey'!D13),ref!$E$6:$F$10,2,0)&" ("&'web survey'!D13&")") -> Good (10) | E15: ='web survey'!S13 | F15: =IF(B15="FU-ACInstall",VLOOKUP(VALUE('web survey'!E13),ref!$B$10:$C$12,2,0)&" ("&'web survey'!E13&")",VLOOKUP(VALUE('web survey'!E13),ref!$E$13:$F$17,2,0)&" ("&'web survey'!E13&")") -> Very Good (10) | G15: ='web survey'!T13 | H15: =IF(B15="FU-ACInstall",VLOOKUP(VALUE('web survey'!F13),ref!$B$15:$C$17,2,0)&" ("&'web survey'!F13&")",VLOOKUP(VALUE('web survey'!F13),ref!$E$20:$F$21,2,0)&" ("&'web survey'!F13&")") -> Appropriate with SAP / in Warranty (10) | I15: ='web survey'!U13 | J15: =IF(B15="FU-ACInstall","-",VLOOKUP(VALUE('web survey'!G13),ref!$E$24:$F$26,2,0)&" ("&'web survey'!G13&")") -> Jelas (5) | K15: =YEAR('web survey'!Z13)&"-"&IF(MONTH('web survey'!Z13)<10,"0"&MONTH('web survey'!Z13),MONTH('web survey'!Z13))&"-"&IF(DAY('web survey'!Z13)<10,"0"&DAY('web survey'!Z13),DAY('web survey'!Z13))&" "&IF(HOUR('web survey'!Z13)<10,"0"&HOUR('web survey'!Z13),HOUR('web survey'!Z13))&":"&IF(MINUTE('web survey'!Z13)<10,"0"&MINUTE('web survey'!Z13),MINUTE('web survey'!Z13))&(":00'") -> 2024-08-21 18:56:00' | N15: 12 | O15: FU-Z1-Eng | P15: 100892571 | Q15: Good (10) | S15: Very Good (10) | U15: Appropriate with SAP / in Warranty (10) | W15: Jelas (5) | X15: 21 Aug 2024 18:56
... A30: =IF(B30="","",ROW()-COUNTBLANK($B$4:B30)-3) -> 27 | B30: ='web survey'!C28 -> FU-Z1-Eng | C30: ='web survey'!AA28 -> 203905676 | D30: =IF(B30="FU-ACInstall",VLOOKUP(VALUE('web survey'!D28),ref!$B$6:$C$7,2,0)&" ("&'web survey'!D28&")",VLOOKUP(VALUE('web survey'!D28),ref!$E$6:$F$10,2,0)&" ("&'web survey'!D28&")") -> Good (10) | E30: ='web survey'!S28 | F30: =IF(B30="FU-ACInstall",VLOOKUP(VALUE('web survey'!E28),ref!$B$10:$C$12,2,0)&" ("&'web survey'!E28&")",VLOOKUP(VALUE('web survey'!E28),ref!$E$13:$F$17,2,0)&" ("&'web survey'!E28&")") -> Very Good (10) | G30: ='web survey'!T28 | H30: =IF(B30="FU-ACInstall",VLOOKUP(VALUE('web survey'!F28),ref!$B$15:$C$17,2,0)&" ("&'web survey'!F28&")",VLOOKUP(VALUE('web survey'!F28),ref!$E$20:$F$21,2,0)&" ("&'web survey'!F28&")") -> Different with SAP (-10) | I30: ='web survey'!U28 | J30: =IF(B30="FU-ACInstall","-",VLOOKUP(VALUE('web survey'!G28),ref!$E$24:$F$26,2,0)&" ("&'web survey'!G28&")") -> Jelas (5) | K30: =YEAR('web survey'!Z28)&"-"&IF(MONTH('web survey'!Z28)<10,"0"&MONTH('web survey'!Z28),MONTH('web survey'!Z28))&"-"&IF(DAY('web survey'!Z28)<10,"0"&DAY('web survey'!Z28),DAY('web survey'!Z28))&" "&IF(HOUR('web survey'!Z28)<10,"0"&HOUR('web survey'!Z28),HOUR('web survey'!Z28))&":"&IF(MINUTE('web survey'!Z28)<10,"0"&MINUTE('web survey'!Z28),MINUTE('web survey'!Z28))&(":00'") -> 2024-08-21 16:58:00' | N30: 27 | O30: FU-Z1-Eng | P30: 203905676 | Q30: Good (10) | S30: Very Good (10) | U30: Different with SAP (-10) | W30: Jelas (5) | X30: 21 Aug 2024 16:58
A31: =IF(B31="","",ROW()-COUNTBLANK($B$4:B31)-3) -> 28 | B31: ='web survey'!C29 -> FU-Z1-Eng | C31: ='web survey'!AA29 -> 203907730 | D31: =IF(B31="FU-ACInstall",VLOOKUP(VALUE('web survey'!D29),ref!$B$6:$C$7,2,0)&" ("&'web survey'!D29&")",VLOOKUP(VALUE('web survey'!D29),ref!$E$6:$F$10,2,0)&" ("&'web survey'!D29&")") -> Not Good (-10) | E31: ='web survey'!S29 -> Instalasi awalnya | F31: =IF(B31="FU-ACInstall",VLOOKUP(VALUE('web survey'!E29),ref!$B$10:$C$12,2,0)&" ("&'web survey'!E29&")",VLOOKUP(VALUE('web survey'!E29),ref!$E$13:$F$17,2,0)&" ("&'web survey'!E29&")") -> Very Good (10) | G31: ='web survey'!T29 | H31: =IF(B31="FU-ACInstall",VLOOKUP(VALUE('web survey'!F29),ref!$B$15:$C$17,2,0)&" ("&'web survey'!F29&")",VLOOKUP(VALUE('web survey'!F29),ref!$E$20:$F$21,2,0)&" ("&'web survey'!F29&")") -> Appropriate with SAP / in Warranty (10) | I31: ='web survey'!U29 | J31: =IF(B31="FU-ACInstall","-",VLOOKUP(VALUE('web survey'!G29),ref!$E$24:$F$26,2,0)&" ("&'web survey'!G29&")") -> Jelas (5) | K31: =YEAR('web survey'!Z29)&"-"&IF(MONTH('web survey'!Z29)<10,"0"&MONTH('web survey'!Z29),MONTH('web survey'!Z29))&"-"&IF(DAY('web survey'!Z29)<10,"0"&DAY('web survey'!Z29),DAY('web survey'!Z29))&" "&IF(HOUR('web survey'!Z29)<10,"0"&HOUR('web survey'!Z29),HOUR('web survey'!Z29))&":"&IF(MINUTE('web survey'!Z29)<10,"0"&MINUTE('web survey'!Z29),MINUTE('web survey'!Z29))&(":00'") -> 2024-08-21 16:52:00' | N31: 28 | O31: FU-Z1-Eng | P31: 203907730 | Q31: Not Good (-10) | R31: Instalasi awalnya | S31: Very Good (10) | U31: Appropriate with SAP / in Warranty (10) | W31: Jelas (5) | X31: 21 Aug 2024 16:52
A32: =IF(B32="","",ROW()-COUNTBLANK($B$4:B32)-3) -> 29 | B32: ='web survey'!C30 -> FU-Z1-Eng | C32: ='web survey'!AA30 -> 203900339 | D32: =IF(B32="FU-ACInstall",VLOOKUP(VALUE('web survey'!D30),ref!$B$6:$C$7,2,0)&" ("&'web survey'!D30&")",VLOOKUP(VALUE('web survey'!D30),ref!$E$6:$F$10,2,0)&" ("&'web survey'!D30&")") -> Good (10) | E32: ='web survey'!S30 | F32: =IF(B32="FU-ACInstall",VLOOKUP(VALUE('web survey'!E30),ref!$B$10:$C$12,2,0)&" ("&'web survey'!E30&")",VLOOKUP(VALUE('web survey'!E30),ref!$E$13:$F$17,2,0)&" ("&'web survey'!E30&")") -> Very Good (10) | G32: ='web survey'!T30 | H32: =IF(B32="FU-ACInstall",VLOOKUP(VALUE('web survey'!F30),ref!$B$15:$C$17,2,0)&" ("&'web survey'!F30&")",VLOOKUP(VALUE('web survey'!F30),ref!$E$20:$F$21,2,0)&" ("&'web survey'!F30&")") -> Appropriate with SAP / in Warranty (10) | I32: ='web survey'!U30 | J32: =IF(B32="FU-ACInstall","-",VLOOKUP(VALUE('web survey'!G30),ref!$E$24:$F$26,2,0)&" ("&'web survey'!G30&")") -> Jelas (5) | K32: =YEAR('web survey'!Z30)&"-"&IF(MONTH('web survey'!Z30)<10,"0"&MONTH('web survey'!Z30),MONTH('web survey'!Z30))&"-"&IF(DAY('web survey'!Z30)<10,"0"&DAY('web survey'!Z30),DAY('web survey'!Z30))&" "&IF(HOUR('web survey'!Z30)<10,"0"&HOUR('web survey'!Z30),HOUR('web survey'!Z30))&":"&IF(MINUTE('web survey'!Z30)<10,"0"&MINUTE('web survey'!Z30),MINUTE('web survey'!Z30))&(":00'") -> 2024-08-21 16:31:00' | N32: 29 | O32: FU-Z1-Eng | P32: 203900339 | Q32: Good (10) | S32: Very Good (10) | U32: Appropriate with SAP / in Warranty (10) | W32: Jelas (5) | X32: 21 Aug 2024 16:31
A33: =IF(B33="","",ROW()-COUNTBLANK($B$4:B33)-3) -> 30 | B33: ='web survey'!C31 -> FU-Z1-Eng | C33: ='web survey'!AA31 -> 203900431 | D33: =IF(B33="FU-ACInstall",VLOOKUP(VALUE('web survey'!D31),ref!$B$6:$C$7,2,0)&" ("&'web survey'!D31&")",VLOOKUP(VALUE('web survey'!D31),ref!$E$6:$F$10,2,0)&" ("&'web survey'!D31&")") -> Good (10) | E33: ='web survey'!S31 | F33: =IF(B33="FU-ACInstall",VLOOKUP(VALUE('web survey'!E31),ref!$B$10:$C$12,2,0)&" ("&'web survey'!E31&")",VLOOKUP(VALUE('web survey'!E31),ref!$E$13:$F$17,2,0)&" ("&'web survey'!E31&")") -> Very Good (10) | G33: ='web survey'!T31 | H33: =IF(B33="FU-ACInstall",VLOOKUP(VALUE('web survey'!F31),ref!$B$15:$C$17,2,0)&" ("&'web survey'!F31&")",VLOOKUP(VALUE('web survey'!F31),ref!$E$20:$F$21,2,0)&" ("&'web survey'!F31&")") -> Appropriate with SAP / in Warranty (10) | I33: ='web survey'!U31 | J33: =IF(B33="FU-ACInstall","-",VLOOKUP(VALUE('web survey'!G31),ref!$E$24:$F$26,2,0)&" ("&'web survey'!G31&")") -> Jelas (5) | K33: =YEAR('web survey'!Z31)&"-"&IF(MONTH('web survey'!Z31)<10,"0"&MONTH('web survey'!Z31),MONTH('web survey'!Z31))&"-"&IF(DAY('web survey'!Z31)<10,"0"&DAY('web survey'!Z31),DAY('web survey'!Z31))&" "&IF(HOUR('web survey'!Z31)<10,"0"&HOUR('web survey'!Z31),HOUR('web survey'!Z31))&":"&IF(MINUTE('web survey'!Z31)<10,"0"&MINUTE('web survey'!Z31),MINUTE('web survey'!Z31))&(":00'") -> 2024-08-21 16:23:00' | N33: 30 | O33: FU-Z1-Eng | P33: 203900431 | Q33: Good (10) | S33: Very Good (10) | U33: Appropriate with SAP / in Warranty (10) | W33: Jelas (5) | X33: 21 Aug 2024 16:23
A34: =IF(B34="","",ROW()-COUNTBLANK($B$4:B34)-3) -> 31 | B34: ='web survey'!C32 -> FU-Z1-Eng | C34: ='web survey'!AA32 -> 1916A2400623 | D34: =IF(B34="FU-ACInstall",VLOOKUP(VALUE('web survey'!D32),ref!$B$6:$C$7,2,0)&" ("&'web survey'!D32&")",VLOOKUP(VALUE('web survey'!D32),ref!$E$6:$F$10,2,0)&" ("&'web survey'!D32&")") -> Good (10) | E34: ='web survey'!S32 | F34: =IF(B34="FU-ACInstall",VLOOKUP(VALUE('web survey'!E32),ref!$B$10:$C$12,2,0)&" ("&'web survey'!E32&")",VLOOKUP(VALUE('web survey'!E32),ref!$E$13:$F$17,2,0)&" ("&'web survey'!E32&")") -> Very Good (10) | G34: ='web survey'!T32 | H34: =IF(B34="FU-ACInstall",VLOOKUP(VALUE('web survey'!F32),ref!$B$15:$C$17,2,0)&" ("&'web survey'!F32&")",VLOOKUP(VALUE('web survey'!F32),ref!$E$20:$F$21,2,0)&" ("&'web survey'!F32&")") -> Appropriate with SAP / in Warranty (10) | I34: ='web survey'!U32 | J34: =IF(B34="FU-ACInstall","-",VLOOKUP(VALUE('web survey'!G32),ref!$E$24:$F$26,2,0)&" ("&'web survey'!G32&")") -> Tidak ada penjelasan (-5) | K34: =YEAR('web survey'!Z32)&"-"&IF(MONTH('web survey'!Z32)<10,"0"&MONTH('web survey'!Z32),MONTH('web survey'!Z32))&"-"&IF(DAY('web survey'!Z32)<10,"0"&DAY('web survey'!Z32),DAY('web survey'!Z32))&" "&IF(HOUR('web survey'!Z32)<10,"0"&HOUR('web survey'!Z32),HOUR('web survey'!Z32))&":"&IF(MINUTE('web survey'!Z32)<10,"0"&MINUTE('web survey'!Z32),MINUTE('web survey'!Z32))&(":00'") -> 2024-08-21 16:17:00' | N34: 31 | O34: FU-Z1-Eng | P34: 1916A2400623 | Q34: Good (10) | S34: Very Good (10) | U34: Appropriate with SAP / in Warranty (10) | W34: Tidak ada penjelasan (-5) | X34: 21 Aug 2024 16:17
A35: =IF(B35="","",ROW()-COUNTBLANK($B$4:B35)-3) -> 32 | B35: ='web survey'!C33 -> FU-Z1-Eng | C35: ='web survey'!AA33 -> 203895647 | D35: =IF(B35="FU-ACInstall",VLOOKUP(VALUE('web survey'!D33),ref!$B$6:$C$7,2,0)&" ("&'web survey'!D33&")",VLOOKUP(VALUE('web survey'!D33),ref!$E$6:$F$10,2,0)&" ("&'web survey'!D33&")") -> Good (10) | E35: ='web survey'!S33 | F35: =IF(B35="FU-ACInstall",VLOOKUP(VALUE('web survey'!E33),ref!$B$10:$C$12,2,0)&" ("&'web survey'!E33&")",VLOOKUP(VALUE('web survey'!E33),ref!$E$13:$F$17,2,0)&" ("&'web survey'!E33&")") -> Very Good (10) | G35: ='web survey'!T33 | H35: =IF(B35="FU-ACInstall",VLOOKUP(VALUE('web survey'!F33),ref!$B$15:$C$17,2,0)&" ("&'web survey'!F33&")",VLOOKUP(VALUE('web survey'!F33),ref!$E$20:$F$21,2,0)&" ("&'web survey'!F33&")") -> Appropriate with SAP / in Warranty (10) | I35: ='web survey'!U33 | J35: =IF(B35="FU-ACInstall","-",VLOOKUP(VALUE('web survey'!G33),ref!$E$24:$F$26,2,0)&" ("&'web survey'!G33&")") -> Jelas (5) | K35: =YEAR('web survey'!Z33)&"-"&IF(MONTH('web survey'!Z33)<10,"0"&MONTH('web survey'!Z33),MONTH('web survey'!Z33))&"-"&IF(DAY('web survey'!Z33)<10,"0"&DAY('web survey'!Z33),DAY('web survey'!Z33))&" "&IF(HOUR('web survey'!Z33)<10,"0"&HOUR('web survey'!Z33),HOUR('web survey'!Z33))&":"&IF(MINUTE('web survey'!Z33)<10,"0"&MINUTE('web survey'!Z33),MINUTE('web survey'!Z33))&(":00'") -> 2024-08-21 16:14:00' | N35: 32 | O35: FU-Z1-Eng | P35: 203895647 | Q35: Good (10) | S35: Very Good (10) | U35: Appropriate with SAP / in Warranty (10) | W35: Jelas (5) | X35: 21 Aug 2024 16:14
A36: =IF(B36="","",ROW()-COUNTBLANK($B$4:B36)-3) -> 33 | B36: ='web survey'!C34 -> FU-Z1-Eng | C36: ='web survey'!AA34 -> 203907620 | D36: =IF(B36="FU-ACInstall",VLOOKUP(VALUE('web survey'!D34),ref!$B$6:$C$7,2,0)&" ("&'web survey'!D34&")",VLOOKUP(VALUE('web survey'!D34),ref!$E$6:$F$10,2,0)&" ("&'web survey'!D34&")") -> Good (10) | E36: ='web survey'!S34 | F36: =IF(B36="FU-ACInstall",VLOOKUP(VALUE('web survey'!E34),ref!$B$10:$C$12,2,0)&" ("&'web survey'!E34&")",VLOOKUP(VALUE('web survey'!E34),ref!$E$13:$F$17,2,0)&" ("&'web survey'!E34&")") -> Very Good (10) | G36: ='web survey'!T34 | H36: =IF(B36="FU-ACInstall",VLOOKUP(VALUE('web survey'!F34),ref!$B$15:$C$17,2,0)&" ("&'web survey'!F34&")",VLOOKUP(VALUE('web survey'!F34),ref!$E$20:$F$21,2,0)&" ("&'web survey'!F34&")") -> Appropriate with SAP / in Warranty (10) | I36: ='web survey'!U34 | J36: =IF(B36="FU-ACInstall","-",VLOOKUP(VALUE('web survey'!G34),ref!$E$24:$F$26,2,0)&" ("&'web survey'!G34&")") -> Jelas (5) | K36: =YEAR('web survey'!Z34)&"-"&IF(MONTH('web survey'!Z34)<10,"0"&MONTH('web survey'!Z34),MONTH('web survey'!Z34))&"-"&IF(DAY('web survey'!Z34)<10,"0"&DAY('web survey'!Z34),DAY('web survey'!Z34))&" "&IF(HOUR('web survey'!Z34)<10,"0"&HOUR('web survey'!Z34),HOUR('web survey'!Z34))&":"&IF(MINUTE('web survey'!Z34)<10,"0"&MINUTE('web survey'!Z34),MINUTE('web survey'!Z34))&(":00'") -> 2024-08-21 16:12:00' | N36: 33 | O36: FU-Z1-Eng | P36: 203907620 | Q36: Good (10) | S36: Very Good (10) | U36: Appropriate with SAP / in Warranty (10) | W36: Jelas (5) | X36: 21 Aug 2024 16:12
A37: =IF(B37="","",ROW()-COUNTBLANK($B$4:B37)-3) -> 34 | B37: ='web survey'!C35 -> FU-Z1-Eng | C37: ='web survey'!AA35 -> 100893588 | D37: =IF(B37="FU-ACInstall",VLOOKUP(VALUE('web survey'!D35),ref!$B$6:$C$7,2,0)&" ("&'web survey'!D35&")",VLOOKUP(VALUE('web survey'!D35),ref!$E$6:$F$10,2,0)&" ("&'web survey'!D35&")") -> Good (10) | E37: ='web survey'!S35 | F37: =IF(B37="FU-ACInstall",VLOOKUP(VALUE('web survey'!E35),ref!$B$10:$C$12,2,0)&" ("&'web survey'!E35&")",VLOOKUP(VALUE('web survey'!E35),ref!$E$13:$F$17,2,0)&" ("&'web survey'!E35&")") -> Very Good (10) | G37: ='web survey'!T35 | H37: =IF(B37="FU-ACInstall",VLOOKUP(VALUE('web survey'!F35),ref!$B$15:$C$17,2,0)&" ("&'web survey'!F35&")",VLOOKUP(VALUE('web survey'!F35),ref!$E$20:$F$21,2,0)&" ("&'web survey'!F35&")") -> Appropriate with SAP / in Warranty (10) | I37: ='web survey'!U35 | J37: =IF(B37="FU-ACInstall","-",VLOOKUP(VALUE('web survey'!G35),ref!$E$24:$F$26,2,0)&" ("&'web survey'!G35&")") -> Jelas (5) | K37: =YEAR('web survey'!Z35)&"-"&IF(MONTH('web survey'!Z35)<10,"0"&MONTH('web survey'!Z35),MONTH('web survey'!Z35))&"-"&IF(DAY('web survey'!Z35)<10,"0"&DAY('web survey'!Z35),DAY('web survey'!Z35))&" "&IF(HOUR('web survey'!Z35)<10,"0"&HOUR('web survey'!Z35),HOUR('web survey'!Z35))&":"&IF(MINUTE('web survey'!Z35)<10,"0"&MINUTE('web survey'!Z35),MINUTE('web survey'!Z35))&(":00'") -> 2024-08-21 16:05:00' | N37: 34 | O37: FU-Z1-Eng | P37: 100893588 | Q37: Good (10) | S37: Very Good (10) | U37: Appropriate with SAP / in Warranty (10) | W37: Jelas (5) | X37: 21 Aug 2024 16:05
A38: =IF(B38="","",ROW()-COUNTBLANK($B$4:B38)-3) -> 35 | B38: ='web survey'!C36 -> FU-Z1-Eng | C38: ='web survey'!AA36 -> 203907538 | D38: =IF(B38="FU-ACInstall",VLOOKUP(VALUE('web survey'!D36),ref!$B$6:$C$7,2,0)&" ("&'web survey'!D36&")",VLOOKUP(VALUE('web survey'!D36),ref!$E$6:$F$10,2,0)&" ("&'web survey'!D36&")") -> Good (10) | E38: ='web survey'!S36 | F38: =IF(B38="FU-ACInstall",VLOOKUP(VALUE('web survey'!E36),ref!$B$10:$C$12,2,0)&" ("&'web survey'!E36&")",VLOOKUP(VALUE('web survey'!E36),ref!$E$13:$F$17,2,0)&" ("&'web survey'!E36&")") -> Good (5) | G38: ='web survey'!T36 | H38: =IF(B38="FU-ACInstall",VLOOKUP(VALUE('web survey'!F36),ref!$B$15:$C$17,2,0)&" ("&'web survey'!F36&")",VLOOKUP(VALUE('web survey'!F36),ref!$E$20:$F$21,2,0)&" ("&'web survey'!F36&")") -> Appropriate with SAP / in Warranty (10) | I38: ='web survey'!U36 | J38: =IF(B38="FU-ACInstall","-",VLOOKUP(VALUE('web survey'!G36),ref!$E$24:$F$26,2,0)&" ("&'web survey'!G36&")") -> Jelas (5) | K38: =YEAR('web survey'!Z36)&"-"&IF(MONTH('web survey'!Z36)<10,"0"&MONTH('web survey'!Z36),MONTH('web survey'!Z36))&"-"&IF(DAY('web survey'!Z36)<10,"0"&DAY('web survey'!Z36),DAY('web survey'!Z36))&" "&IF(HOUR('web survey'!Z36)<10,"0"&HOUR('web survey'!Z36),HOUR('web survey'!Z36))&":"&IF(MINUTE('web survey'!Z36)<10,"0"&MINUTE('web survey'!Z36),MINUTE('web survey'!Z36))&(":00'") -> 2024-08-21 15:56:00' | N38: 35 | O38: FU-Z1-Eng | P38: 203907538 | Q38: Good (10) | S38: Good (5) | U38: Appropriate with SAP / in Warranty (10) | W38: Jelas (5) | X38: 21 Aug 2024 15:56
A39: =IF(B39="","",ROW()-COUNTBLANK($B$4:B39)-3) -> 36 | B39: ='web survey'!C37 -> FU-Z1-Eng | C39: ='web survey'!AA37 -> 203901930 | D39: =IF(B39="FU-ACInstall",VLOOKUP(VALUE('web survey'!D37),ref!$B$6:$C$7,2,0)&" ("&'web survey'!D37&")",VLOOKUP(VALUE('web survey'!D37),ref!$E$6:$F$10,2,0)&" ("&'web survey'!D37&")") -> Good (10) | E39: ='web survey'!S37 | F39: =IF(B39="FU-ACInstall",VLOOKUP(VALUE('web survey'!E37),ref!$B$10:$C$12,2,0)&" ("&'web survey'!E37&")",VLOOKUP(VALUE('web survey'!E37),ref!$E$13:$F$17,2,0)&" ("&'web survey'!E37&")") -> Average (3) | G39: ='web survey'!T37 | H39: =IF(B39="FU-ACInstall",VLOOKUP(VALUE('web survey'!F37),ref!$B$15:$C$17,2,0)&" ("&'web survey'!F37&")",VLOOKUP(VALUE('web survey'!F37),ref!$E$20:$F$21,2,0)&" ("&'web survey'!F37&")") -> Appropriate with SAP / in Warranty (10) | I39: ='web survey'!U37 | J39: =IF(B39="FU-ACInstall","-",VLOOKUP(VALUE('web survey'!G37),ref!$E$24:$F$26,2,0)&" ("&'web survey'!G37&")") -> Jelas (5) | K39: =YEAR('web survey'!Z37)&"-"&IF(MONTH('web survey'!Z37)<10,"0"&MONTH('web survey'!Z37),MONTH('web survey'!Z37))&"-"&IF(DAY('web survey'!Z37)<10,"0"&DAY('web survey'!Z37),DAY('web survey'!Z37))&" "&IF(HOUR('web survey'!Z37)<10,"0"&HOUR('web survey'!Z37),HOUR('web survey'!Z37))&":"&IF(MINUTE('web survey'!Z37)<10,"0"&MINUTE('web survey'!Z37),MINUTE('web survey'!Z37))&(":00'") -> 2024-08-21 15:54:00' | N39: 36 | O39: FU-Z1-Eng | P39: 203901930 | Q39: Good (10) | S39: Average (3) | U39: Appropriate with SAP / in Warranty (10) | W39: Jelas (5) | X39: 21 Aug 2024 15:54
A40: =IF(B40="","",ROW()-COUNTBLANK($B$4:B40)-3) -> 37 | B40: ='web survey'!C38 -> FU-Z1-Eng | C40: ='web survey'!AA38 -> 203907595 | D40: =IF(B40="FU-ACInstall",VLOOKUP(VALUE('web survey'!D38),ref!$B$6:$C$7,2,0)&" ("&'web survey'!D38&")",VLOOKUP(VALUE('web survey'!D38),ref!$E$6:$F$10,2,0)&" ("&'web survey'!D38&")") -> Good (10) | E40: ='web survey'!S38 | F40: =IF(B40="FU-ACInstall",VLOOKUP(VALUE('web survey'!E38),ref!$B$10:$C$12,2,0)&" ("&'web survey'!E38&")",VLOOKUP(VALUE('web survey'!E38),ref!$E$13:$F$17,2,0)&" ("&'web survey'!E38&")") -> Very Good (10) | G40: ='web survey'!T38 | H40: =IF(B40="FU-ACInstall",VLOOKUP(VALUE('web survey'!F38),ref!$B$15:$C$17,2,0)&" ("&'web survey'!F38&")",VLOOKUP(VALUE('web survey'!F38),ref!$E$20:$F$21,2,0)&" ("&'web survey'!F38&")") -> Appropriate with SAP / in Warranty (10) | I40: ='web survey'!U38 | J40: =IF(B40="FU-ACInstall","-",VLOOKUP(VALUE('web survey'!G38),ref!$E$24:$F$26,2,0)&" ("&'web survey'!G38&")") -> Jelas (5) | K40: =YEAR('web survey'!Z38)&"-"&IF(MONTH('web survey'!Z38)<10,"0"&MONTH('web survey'!Z38),MONTH('web survey'!Z38))&"-"&IF(DAY('web survey'!Z38)<10,"0"&DAY('web survey'!Z38),DAY('web survey'!Z38))&" "&IF(HOUR('web survey'!Z38)<10,"0"&HOUR('web survey'!Z38),HOUR('web survey'!Z38))&":"&IF(MINUTE('web survey'!Z38)<10,"0"&MINUTE('web survey'!Z38),MINUTE('web survey'!Z38))&(":00'") -> 2024-08-21 15:53:00' | N40: 37 | O40: FU-Z1-Eng | P40: 203907595 | Q40: Good (10) | S40: Very Good (10) | U40: Appropriate with SAP / in Warranty (10) | W40: Jelas (5) | X40: 21 Aug 2024 15:53
A41: =IF(B41="","",ROW()-COUNTBLANK($B$4:B41)-3) -> 38 | B41: ='web survey'!C39 -> FU-Z1-Eng | C41: ='web survey'!AA39 -> 100891707 | D41: =IF(B41="FU-ACInstall",VLOOKUP(VALUE('web survey'!D39),ref!$B$6:$C$7,2,0)&" ("&'web survey'!D39&")",VLOOKUP(VALUE('web survey'!D39),ref!$E$6:$F$10,2,0)&" ("&'web survey'!D39&")") -> Good (10) | E41: ='web survey'!S39 | F41: =IF(B41="FU-ACInstall",VLOOKUP(VALUE('web survey'!E39),ref!$B$10:$C$12,2,0)&" ("&'web survey'!E39&")",VLOOKUP(VALUE('web survey'!E39),ref!$E$13:$F$17,2,0)&" ("&'web survey'!E39&")") -> Good (5) | G41: ='web survey'!T39 | H41: =IF(B41="FU-ACInstall",VLOOKUP(VALUE('web survey'!F39),ref!$B$15:$C$17,2,0)&" ("&'web survey'!F39&")",VLOOKUP(VALUE('web survey'!F39),ref!$E$20:$F$21,2,0)&" ("&'web survey'!F39&")") -> Different with SAP (-10) | I41: ='web survey'!U39 | J41: =IF(B41="FU-ACInstall","-",VLOOKUP(VALUE('web survey'!G39),ref!$E$24:$F$26,2,0)&" ("&'web survey'!G39&")") -> Jelas (5) | K41: =YEAR('web survey'!Z39)&"-"&IF(MONTH('web survey'!Z39)<10,"0"&MONTH('web survey'!Z39),MONTH('web survey'!Z39))&"-"&IF(DAY('web survey'!Z39)<10,"0"&DAY('web survey'!Z39),DAY('web survey'!Z39))&" "&IF(HOUR('web survey'!Z39)<10,"0"&HOUR('web survey'!Z39),HOUR('web survey'!Z39))&":"&IF(MINUTE('web survey'!Z39)<10,"0"&MINUTE('web survey'!Z39),MINUTE('web survey'!Z39))&(":00'") -> 2024-08-21 15:50:00' | N41: 38 | O41: FU-Z1-Eng | P41: 100891707 | Q41: Good (10) | S41: Good (5) | U41: Different with SAP (-10) | W41: Jelas (5) | X41: 21 Aug 2024 15:50
A42: =IF(B42="","",ROW()-COUNTBLANK($B$4:B42)-3) -> 39 | B42: ='web survey'!C40 -> FU-Z1-Eng | C42: ='web survey'!AA40 -> 203909251 | D42: =IF(B42="FU-ACInstall",VLOOKUP(VALUE('web survey'!D40),ref!$B$6:$C$7,2,0)&" ("&'web survey'!D40&")",VLOOKUP(VALUE('web survey'!D40),ref!$E$6:$F$10,2,0)&" ("&'web survey'!D40&")") -> Good (10) | E42: ='web survey'!S40 | F42: =IF(B42="FU-ACInstall",VLOOKUP(VALUE('web survey'!E40),ref!$B$10:$C$12,2,0)&" ("&'web survey'!E40&")",VLOOKUP(VALUE('web survey'!E40),ref!$E$13:$F$17,2,0)&" ("&'web survey'!E40&")") -> Very Good (10) | G42: ='web survey'!T40 | H42: =IF(B42="FU-ACInstall",VLOOKUP(VALUE('web survey'!F40),ref!$B$15:$C$17,2,0)&" ("&'web survey'!F40&")",VLOOKUP(VALUE('web survey'!F40),ref!$E$20:$F$21,2,0)&" ("&'web survey'!F40&")") -> Different with SAP (-10) | I42: ='web survey'!U40 | J42: =IF(B42="FU-ACInstall","-",VLOOKUP(VALUE('web survey'!G40),ref!$E$24:$F$26,2,0)&" ("&'web survey'!G40&")") -> Jelas (5) | K42: =YEAR('web survey'!Z40)&"-"&IF(MONTH('web survey'!Z40)<10,"0"&MONTH('web survey'!Z40),MONTH('web survey'!Z40))&"-"&IF(DAY('web survey'!Z40)<10,"0"&DAY('web survey'!Z40),DAY('web survey'!Z40))&" "&IF(HOUR('web survey'!Z40)<10,"0"&HOUR('web survey'!Z40),HOUR('web survey'!Z40))&":"&IF(MINUTE('web survey'!Z40)<10,"0"&MINUTE('web survey'!Z40),MINUTE('web survey'!Z40))&(":00'") -> 2024-08-21 15:49:00' | N42: 39 | O42: FU-Z1-Eng | P42: 203909251 | Q42: Good (10) | S42: Very Good (10) | U42: Different with SAP (-10) | W42: Jelas (5) | X42: 21 Aug 2024 15:49
A43: =IF(B43="","",ROW()-COUNTBLANK($B$4:B43)-3) -> 40 | B43: ='web survey'!C41 -> FU-Z1-Eng | C43: ='web survey'!AA41 -> 203904127 | D43: =IF(B43="FU-ACInstall",VLOOKUP(VALUE('web survey'!D41),ref!$B$6:$C$7,2,0)&" ("&'web survey'!D41&")",VLOOKUP(VALUE('web survey'!D41),ref!$E$6:$F$10,2,0)&" ("&'web survey'!D41&")") -> Good (10) | E43: ='web survey'!S41 | F43: =IF(B43="FU-ACInstall",VLOOKUP(VALUE('web survey'!E41),ref!$B$10:$C$12,2,0)&" ("&'web survey'!E41&")",VLOOKUP(VALUE('web survey'!E41),ref!$E$13:$F$17,2,0)&" ("&'web survey'!E41&")") -> Very Good (10) | G43: ='web survey'!T41 | H43: =IF(B43="FU-ACInstall",VLOOKUP(VALUE('web survey'!F41),ref!$B$15:$C$17,2,0)&" ("&'web survey'!F41&")",VLOOKUP(VALUE('web survey'!F41),ref!$E$20:$F$21,2,0)&" ("&'web survey'!F41&")") -> Different with SAP (-10) | I43: ='web survey'!U41 | J43: =IF(B43="FU-ACInstall","-",VLOOKUP(VALUE('web survey'!G41),ref!$E$24:$F$26,2,0)&" ("&'web survey'!G41&")") -> Jelas (5) | K43: =YEAR('web survey'!Z41)&"-"&IF(MONTH('web survey'!Z41)<10,"0"&MONTH('web survey'!Z41),MONTH('web survey'!Z41))&"-"&IF(DAY('web survey'!Z41)<10,"0"&DAY('web survey'!Z41),DAY('web survey'!Z41))&" "&IF(HOUR('web survey'!Z41)<10,"0"&HOUR('web survey'!Z41),HOUR('web survey'!Z41))&":"&IF(MINUTE('web survey'!Z41)<10,"0"&MINUTE('web survey'!Z41),MINUTE('web survey'!Z41))&(":00'") -> 2024-08-21 15:44:00' | N43: 40 | O43: FU-Z1-Eng | P43: 203904127 | Q43: Good (10) | S43: Very Good (10) | U43: Different with SAP (-10) | W43: Jelas (5) | X43: 21 Aug 2024 15:44
... A64: =IF(B64="","",ROW()-COUNTBLANK($B$4:B64)-3) -> 61 | B64: ='web survey'!C62 -> FU-Z1-Eng | C64: ='web survey'!AA62 -> 203907152 | D64: =IF(B64="FU-ACInstall",VLOOKUP(VALUE('web survey'!D62),ref!$B$6:$C$7,2,0)&" ("&'web survey'!D62&")",VLOOKUP(VALUE('web survey'!D62),ref!$E$6:$F$10,2,0)&" ("&'web survey'!D62&")") -> Good (10) | E64: ='web survey'!S62 | F64: =IF(B64="FU-ACInstall",VLOOKUP(VALUE('web survey'!E62),ref!$B$10:$C$12,2,0)&" ("&'web survey'!E62&")",VLOOKUP(VALUE('web survey'!E62),ref!$E$13:$F$17,2,0)&" ("&'web survey'!E62&")") -> Good (5) | G64: ='web survey'!T62 | H64: =IF(B64="FU-ACInstall",VLOOKUP(VALUE('web survey'!F62),ref!$B$15:$C$17,2,0)&" ("&'web survey'!F62&")",VLOOKUP(VALUE('web survey'!F62),ref!$E$20:$F$21,2,0)&" ("&'web survey'!F62&")") -> Appropriate with SAP / in Warranty (10) | I64: ='web survey'!U62 | J64: =IF(B64="FU-ACInstall","-",VLOOKUP(VALUE('web survey'!G62),ref!$E$24:$F$26,2,0)&" ("&'web survey'!G62&")") -> Jelas (5) | K64: =YEAR('web survey'!Z62)&"-"&IF(MONTH('web survey'!Z62)<10,"0"&MONTH('web survey'!Z62),MONTH('web survey'!Z62))&"-"&IF(DAY('web survey'!Z62)<10,"0"&DAY('web survey'!Z62),DAY('web survey'!Z62))&" "&IF(HOUR('web survey'!Z62)<10,"0"&HOUR('web survey'!Z62),HOUR('web survey'!Z62))&":"&IF(MINUTE('web survey'!Z62)<10,"0"&MINUTE('web survey'!Z62),MINUTE('web survey'!Z62))&(":00'") -> 2024-08-21 15:14:00' | N64: 61 | O64: FU-Z1-Eng | P64: 203907152 | Q64: Good (10) | S64: Good (5) | U64: Appropriate with SAP / in Warranty (10) | W64: Jelas (5) | X64: 21 Aug 2024 15:14
A65: =IF(B65="","",ROW()-COUNTBLANK($B$4:B65)-3) -> 62 | B65: ='web survey'!C63 -> FU-Z1-Eng | C65: ='web survey'!AA63 -> 203907272 | D65: =IF(B65="FU-ACInstall",VLOOKUP(VALUE('web survey'!D63),ref!$B$6:$C$7,2,0)&" ("&'web survey'!D63&")",VLOOKUP(VALUE('web survey'!D63),ref!$E$6:$F$10,2,0)&" ("&'web survey'!D63&")") -> Not Good (-10) | E65: ='web survey'!S63 -> Gak jelas | F65: =IF(B65="FU-ACInstall",VLOOKUP(VALUE('web survey'!E63),ref!$B$10:$C$12,2,0)&" ("&'web survey'!E63&")",VLOOKUP(VALUE('web survey'!E63),ref!$E$13:$F$17,2,0)&" ("&'web survey'!E63&")") -> Average (3) | G65: ='web survey'!T63 | H65: =IF(B65="FU-ACInstall",VLOOKUP(VALUE('web survey'!F63),ref!$B$15:$C$17,2,0)&" ("&'web survey'!F63&")",VLOOKUP(VALUE('web survey'!F63),ref!$E$20:$F$21,2,0)&" ("&'web survey'!F63&")") -> Different with SAP (-10) | I65: ='web survey'!U63 | J65: =IF(B65="FU-ACInstall","-",VLOOKUP(VALUE('web survey'!G63),ref!$E$24:$F$26,2,0)&" ("&'web survey'!G63&")") -> Kurang jelas (3) | K65: =YEAR('web survey'!Z63)&"-"&IF(MONTH('web survey'!Z63)<10,"0"&MONTH('web survey'!Z63),MONTH('web survey'!Z63))&"-"&IF(DAY('web survey'!Z63)<10,"0"&DAY('web survey'!Z63),DAY('web survey'!Z63))&" "&IF(HOUR('web survey'!Z63)<10,"0"&HOUR('web survey'!Z63),HOUR('web survey'!Z63))&":"&IF(MINUTE('web survey'!Z63)<10,"0"&MINUTE('web survey'!Z63),MINUTE('web survey'!Z63))&(":00'") -> 2024-08-21 15:14:00' | N65: 62 | O65: FU-Z1-Eng | P65: 203907272 | Q65: Not Good (-10) | R65: Gak jelas | S65: Average (3) | U65: Different with SAP (-10) | W65: Kurang jelas (3) | X65: 21 Aug 2024 15:14
A66: =IF(B66="","",ROW()-COUNTBLANK($B$4:B66)-3) -> 63 | B66: ='web survey'!C64 -> FU-Z1-Eng | C66: ='web survey'!AA64 -> 203905018 | D66: =IF(B66="FU-ACInstall",VLOOKUP(VALUE('web survey'!D64),ref!$B$6:$C$7,2,0)&" ("&'web survey'!D64&")",VLOOKUP(VALUE('web survey'!D64),ref!$E$6:$F$10,2,0)&" ("&'web survey'!D64&")") -> Good (10) | E66: ='web survey'!S64 | F66: =IF(B66="FU-ACInstall",VLOOKUP(VALUE('web survey'!E64),ref!$B$10:$C$12,2,0)&" ("&'web survey'!E64&")",VLOOKUP(VALUE('web survey'!E64),ref!$E$13:$F$17,2,0)&" ("&'web survey'!E64&")") -> Very Good (10) | G66: ='web survey'!T64 | H66: =IF(B66="FU-ACInstall",VLOOKUP(VALUE('web survey'!F64),ref!$B$15:$C$17,2,0)&" ("&'web survey'!F64&")",VLOOKUP(VALUE('web survey'!F64),ref!$E$20:$F$21,2,0)&" ("&'web survey'!F64&")") -> Appropriate with SAP / in Warranty (10) | I66: ='web survey'!U64 | J66: =IF(B66="FU-ACInstall","-",VLOOKUP(VALUE('web survey'!G64),ref!$E$24:$F$26,2,0)&" ("&'web survey'!G64&")") -> Jelas (5) | K66: =YEAR('web survey'!Z64)&"-"&IF(MONTH('web survey'!Z64)<10,"0"&MONTH('web survey'!Z64),MONTH('web survey'!Z64))&"-"&IF(DAY('web survey'!Z64)<10,"0"&DAY('web survey'!Z64),DAY('web survey'!Z64))&" "&IF(HOUR('web survey'!Z64)<10,"0"&HOUR('web survey'!Z64),HOUR('web survey'!Z64))&":"&IF(MINUTE('web survey'!Z64)<10,"0"&MINUTE('web survey'!Z64),MINUTE('web survey'!Z64))&(":00'") -> 2024-08-21 15:14:00' | N66: 63 | O66: FU-Z1-Eng | P66: 203905018 | Q66: Good (10) | S66: Very Good (10) | U66: Appropriate with SAP / in Warranty (10) | W66: Jelas (5) | X66: 21 Aug 2024 15:14
A67: =IF(B67="","",ROW()-COUNTBLANK($B$4:B67)-3) -> 64 | B67: ='web survey'!C65 -> FU-Z1-Eng | C67: ='web survey'!AA65 -> 203907735 | D67: =IF(B67="FU-ACInstall",VLOOKUP(VALUE('web survey'!D65),ref!$B$6:$C$7,2,0)&" ("&'web survey'!D65&")",VLOOKUP(VALUE('web survey'!D65),ref!$E$6:$F$10,2,0)&" ("&'web survey'!D65&")") -> Good (10) | E67: ='web survey'!S65 | F67: =IF(B67="FU-ACInstall",VLOOKUP(VALUE('web survey'!E65),ref!$B$10:$C$12,2,0)&" ("&'web survey'!E65&")",VLOOKUP(VALUE('web survey'!E65),ref!$E$13:$F$17,2,0)&" ("&'web survey'!E65&")") -> Good (5) | G67: ='web survey'!T65 | H67: =IF(B67="FU-ACInstall",VLOOKUP(VALUE('web survey'!F65),ref!$B$15:$C$17,2,0)&" ("&'web survey'!F65&")",VLOOKUP(VALUE('web survey'!F65),ref!$E$20:$F$21,2,0)&" ("&'web survey'!F65&")") -> Appropriate with SAP / in Warranty (10) | I67: ='web survey'!U65 | J67: =IF(B67="FU-ACInstall","-",VLOOKUP(VALUE('web survey'!G65),ref!$E$24:$F$26,2,0)&" ("&'web survey'!G65&")") -> Jelas (5) | K67: =YEAR('web survey'!Z65)&"-"&IF(MONTH('web survey'!Z65)<10,"0"&MONTH('web survey'!Z65),MONTH('web survey'!Z65))&"-"&IF(DAY('web survey'!Z65)<10,"0"&DAY('web survey'!Z65),DAY('web survey'!Z65))&" "&IF(HOUR('web survey'!Z65)<10,"0"&HOUR('web survey'!Z65),HOUR('web survey'!Z65))&":"&IF(MINUTE('web survey'!Z65)<10,"0"&MINUTE('web survey'!Z65),MINUTE('web survey'!Z65))&(":00'") -> 2024-08-21 15:14:00' | N67: 64 | O67: FU-Z1-Eng | P67: 203907735 | Q67: Good (10) | S67: Good (5) | U67: Appropriate with SAP / in Warranty (10) | W67: Jelas (5) | X67: 21 Aug 2024 15:14
A68: =IF(B68="","",ROW()-COUNTBLANK($B$4:B68)-3) -> 65 | B68: ='web survey'!C66 -> FU-Z1-Eng | C68: ='web survey'!AA66 -> 203907505 | D68: =IF(B68="FU-ACInstall",VLOOKUP(VALUE('web survey'!D66),ref!$B$6:$C$7,2,0)&" ("&'web survey'!D66&")",VLOOKUP(VALUE('web survey'!D66),ref!$E$6:$F$10,2,0)&" ("&'web survey'!D66&")") -> Good (10) | E68: ='web survey'!S66 | F68: =IF(B68="FU-ACInstall",VLOOKUP(VALUE('web survey'!E66),ref!$B$10:$C$12,2,0)&" ("&'web survey'!E66&")",VLOOKUP(VALUE('web survey'!E66),ref!$E$13:$F$17,2,0)&" ("&'web survey'!E66&")") -> Very Good (10) | G68: ='web survey'!T66 | H68: =IF(B68="FU-ACInstall",VLOOKUP(VALUE('web survey'!F66),ref!$B$15:$C$17,2,0)&" ("&'web survey'!F66&")",VLOOKUP(VALUE('web survey'!F66),ref!$E$20:$F$21,2,0)&" ("&'web survey'!F66&")") -> Appropriate with SAP / in Warranty (10) | I68: ='web survey'!U66 | J68: =IF(B68="FU-ACInstall","-",VLOOKUP(VALUE('web survey'!G66),ref!$E$24:$F$26,2,0)&" ("&'web survey'!G66&")") -> Jelas (5) | K68: =YEAR('web survey'!Z66)&"-"&IF(MONTH('web survey'!Z66)<10,"0"&MONTH('web survey'!Z66),MONTH('web survey'!Z66))&"-"&IF(DAY('web survey'!Z66)<10,"0"&DAY('web survey'!Z66),DAY('web survey'!Z66))&" "&IF(HOUR('web survey'!Z66)<10,"0"&HOUR('web survey'!Z66),HOUR('web survey'!Z66))&":"&IF(MINUTE('web survey'!Z66)<10,"0"&MINUTE('web survey'!Z66),MINUTE('web survey'!Z66))&(":00'") -> 2024-08-21 15:13:00' | N68: 65 | O68: FU-Z1-Eng | P68: 203907505 | Q68: Good (10) | S68: Very Good (10) | U68: Appropriate with SAP / in Warranty (10) | W68: Jelas (5) | X68: 21 Aug 2024 15:13
A69: =IF(B69="","",ROW()-COUNTBLANK($B$4:B69)-3) -> 66 | B69: ='web survey'!C67 -> FU-Z1-Eng | C69: ='web survey'!AA67 -> 100893407 | D69: =IF(B69="FU-ACInstall",VLOOKUP(VALUE('web survey'!D67),ref!$B$6:$C$7,2,0)&" ("&'web survey'!D67&")",VLOOKUP(VALUE('web survey'!D67),ref!$E$6:$F$10,2,0)&" ("&'web survey'!D67&")") -> Good (10) | E69: ='web survey'!S67 | F69: =IF(B69="FU-ACInstall",VLOOKUP(VALUE('web survey'!E67),ref!$B$10:$C$12,2,0)&" ("&'web survey'!E67&")",VLOOKUP(VALUE('web survey'!E67),ref!$E$13:$F$17,2,0)&" ("&'web survey'!E67&")") -> Very Good (10) | G69: ='web survey'!T67 | H69: =IF(B69="FU-ACInstall",VLOOKUP(VALUE('web survey'!F67),ref!$B$15:$C$17,2,0)&" ("&'web survey'!F67&")",VLOOKUP(VALUE('web survey'!F67),ref!$E$20:$F$21,2,0)&" ("&'web survey'!F67&")") -> Appropriate with SAP / in Warranty (10) | I69: ='web survey'!U67 | J69: =IF(B69="FU-ACInstall","-",VLOOKUP(VALUE('web survey'!G67),ref!$E$24:$F$26,2,0)&" ("&'web survey'!G67&")") -> Jelas (5) | K69: =YEAR('web survey'!Z67)&"-"&IF(MONTH('web survey'!Z67)<10,"0"&MONTH('web survey'!Z67),MONTH('web survey'!Z67))&"-"&IF(DAY('web survey'!Z67)<10,"0"&DAY('web survey'!Z67),DAY('web survey'!Z67))&" "&IF(HOUR('web survey'!Z67)<10,"0"&HOUR('web survey'!Z67),HOUR('web survey'!Z67))&":"&IF(MINUTE('web survey'!Z67)<10,"0"&MINUTE('web survey'!Z67),MINUTE('web survey'!Z67))&(":00'") -> 2024-08-21 15:13:00' | N69: 66 | O69: FU-Z1-Eng | P69: 100893407 | Q69: Good (10) | S69: Very Good (10) | U69: Appropriate with SAP / in Warranty (10) | W69: Jelas (5) | X69: 21 Aug 2024 15:13
A70: =IF(B70="","",ROW()-COUNTBLANK($B$4:B70)-3) -> 67 | B70: ='web survey'!C68 -> FU-Z1-Eng | C70: ='web survey'!AA68 -> 203900645 | D70: =IF(B70="FU-ACInstall",VLOOKUP(VALUE('web survey'!D68),ref!$B$6:$C$7,2,0)&" ("&'web survey'!D68&")",VLOOKUP(VALUE('web survey'!D68),ref!$E$6:$F$10,2,0)&" ("&'web survey'!D68&")") -> Good (10) | E70: ='web survey'!S68 | F70: =IF(B70="FU-ACInstall",VLOOKUP(VALUE('web survey'!E68),ref!$B$10:$C$12,2,0)&" ("&'web survey'!E68&")",VLOOKUP(VALUE('web survey'!E68),ref!$E$13:$F$17,2,0)&" ("&'web survey'!E68&")") -> Very Good (10) | G70: ='web survey'!T68 | H70: =IF(B70="FU-ACInstall",VLOOKUP(VALUE('web survey'!F68),ref!$B$15:$C$17,2,0)&" ("&'web survey'!F68&")",VLOOKUP(VALUE('web survey'!F68),ref!$E$20:$F$21,2,0)&" ("&'web survey'!F68&")") -> Appropriate with SAP / in Warranty (10) | I70: ='web survey'!U68 | J70: =IF(B70="FU-ACInstall","-",VLOOKUP(VALUE('web survey'!G68),ref!$E$24:$F$26,2,0)&" ("&'web survey'!G68&")") -> Jelas (5) | K70: =YEAR('web survey'!Z68)&"-"&IF(MONTH('web survey'!Z68)<10,"0"&MONTH('web survey'!Z68),MONTH('web survey'!Z68))&"-"&IF(DAY('web survey'!Z68)<10,"0"&DAY('web survey'!Z68),DAY('web survey'!Z68))&" "&IF(HOUR('web survey'!Z68)<10,"0"&HOUR('web survey'!Z68),HOUR('web survey'!Z68))&":"&IF(MINUTE('web survey'!Z68)<10,"0"&MINUTE('web survey'!Z68),MINUTE('web survey'!Z68))&(":00'") -> 2024-08-21 15:12:00' | N70: 67 | O70: FU-Z1-Eng | P70: 203900645 | Q70: Good (10) | S70: Very Good (10) | U70: Appropriate with SAP / in Warranty (10) | W70: Jelas (5) | X70: 21 Aug 2024 15:12
A71: =IF(B71="","",ROW()-COUNTBLANK($B$4:B71)-3) -> 68 | B71: ='web survey'!C69 -> FU-Z1-Eng | C71: ='web survey'!AA69 -> 100893627 | D71: =IF(B71="FU-ACInstall",VLOOKUP(VALUE('web survey'!D69),ref!$B$6:$C$7,2,0)&" ("&'web survey'!D69&")",VLOOKUP(VALUE('web survey'!D69),ref!$E$6:$F$10,2,0)&" ("&'web survey'!D69&")") -> Good (10) | E71: ='web survey'!S69 | F71: =IF(B71="FU-ACInstall",VLOOKUP(VALUE('web survey'!E69),ref!$B$10:$C$12,2,0)&" ("&'web survey'!E69&")",VLOOKUP(VALUE('web survey'!E69),ref!$E$13:$F$17,2,0)&" ("&'web survey'!E69&")") -> Not Fairly Good (-5) | G71: ='web survey'!T69 | H71: =IF(B71="FU-ACInstall",VLOOKUP(VALUE('web survey'!F69),ref!$B$15:$C$17,2,0)&" ("&'web survey'!F69&")",VLOOKUP(VALUE('web survey'!F69),ref!$E$20:$F$21,2,0)&" ("&'web survey'!F69&")") -> Appropriate with SAP / in Warranty (10) | I71: ='web survey'!U69 | J71: =IF(B71="FU-ACInstall","-",VLOOKUP(VALUE('web survey'!G69),ref!$E$24:$F$26,2,0)&" ("&'web survey'!G69&")") -> Kurang jelas (3) | K71: =YEAR('web survey'!Z69)&"-"&IF(MONTH('web survey'!Z69)<10,"0"&MONTH('web survey'!Z69),MONTH('web survey'!Z69))&"-"&IF(DAY('web survey'!Z69)<10,"0"&DAY('web survey'!Z69),DAY('web survey'!Z69))&" "&IF(HOUR('web survey'!Z69)<10,"0"&HOUR('web survey'!Z69),HOUR('web survey'!Z69))&":"&IF(MINUTE('web survey'!Z69)<10,"0"&MINUTE('web survey'!Z69),MINUTE('web survey'!Z69))&(":00'") -> 2024-08-21 15:11:00' | N71: 68 | O71: FU-Z1-Eng | P71: 100893627 | Q71: Good (10) | S71: Not Fairly Good (-5) | U71: Appropriate with SAP / in Warranty (10) | W71: Kurang jelas (3) | X71: 21 Aug 2024 15:11
A72: =IF(B72="","",ROW()-COUNTBLANK($B$4:B72)-3) -> 69 | B72: ='web survey'!C70 -> FU-Z1-Eng | C72: ='web survey'!AA70 -> 203902202 | D72: =IF(B72="FU-ACInstall",VLOOKUP(VALUE('web survey'!D70),ref!$B$6:$C$7,2,0)&" ("&'web survey'!D70&")",VLOOKUP(VALUE('web survey'!D70),ref!$E$6:$F$10,2,0)&" ("&'web survey'!D70&")") -> Good (10) | E72: ='web survey'!S70 | F72: =IF(B72="FU-ACInstall",VLOOKUP(VALUE('web survey'!E70),ref!$B$10:$C$12,2,0)&" ("&'web survey'!E70&")",VLOOKUP(VALUE('web survey'!E70),ref!$E$13:$F$17,2,0)&" ("&'web survey'!E70&")") -> Very Good (10) | G72: ='web survey'!T70 | H72: =IF(B72="FU-ACInstall",VLOOKUP(VALUE('web survey'!F70),ref!$B$15:$C$17,2,0)&" ("&'web survey'!F70&")",VLOOKUP(VALUE('web survey'!F70),ref!$E$20:$F$21,2,0)&" ("&'web survey'!F70&")") -> Appropriate with SAP / in Warranty (10) | I72: ='web survey'!U70 | J72: =IF(B72="FU-ACInstall","-",VLOOKUP(VALUE('web survey'!G70),ref!$E$24:$F$26,2,0)&" ("&'web survey'!G70&")") -> Jelas (5) | K72: =YEAR('web survey'!Z70)&"-"&IF(MONTH('web survey'!Z70)<10,"0"&MONTH('web survey'!Z70),MONTH('web survey'!Z70))&"-"&IF(DAY('web survey'!Z70)<10,"0"&DAY('web survey'!Z70),DAY('web survey'!Z70))&" "&IF(HOUR('web survey'!Z70)<10,"0"&HOUR('web survey'!Z70),HOUR('web survey'!Z70))&":"&IF(MINUTE('web survey'!Z70)<10,"0"&MINUTE('web survey'!Z70),MINUTE('web survey'!Z70))&(":00'") -> 2024-08-21 15:11:00' | N72: 69 | O72: FU-Z1-Eng | P72: 203902202 | Q72: Good (10) | S72: Very Good (10) | U72: Appropriate with SAP / in Warranty (10) | W72: Jelas (5) | X72: 21 Aug 2024 15:11
A73: =IF(B73="","",ROW()-COUNTBLANK($B$4:B73)-3) -> 70 | B73: ='web survey'!C71 -> FU-Z1-Eng | C73: ='web survey'!AA71 -> 203903396 | D73: =IF(B73="FU-ACInstall",VLOOKUP(VALUE('web survey'!D71),ref!$B$6:$C$7,2,0)&" ("&'web survey'!D71&")",VLOOKUP(VALUE('web survey'!D71),ref!$E$6:$F$10,2,0)&" ("&'web survey'!D71&")") -> Good (10) | E73: ='web survey'!S71 | F73: =IF(B73="FU-ACInstall",VLOOKUP(VALUE('web survey'!E71),ref!$B$10:$C$12,2,0)&" ("&'web survey'!E71&")",VLOOKUP(VALUE('web survey'!E71),ref!$E$13:$F$17,2,0)&" ("&'web survey'!E71&")") -> Good (5) | G73: ='web survey'!T71 | H73: =IF(B73="FU-ACInstall",VLOOKUP(VALUE('web survey'!F71),ref!$B$15:$C$17,2,0)&" ("&'web survey'!F71&")",VLOOKUP(VALUE('web survey'!F71),ref!$E$20:$F$21,2,0)&" ("&'web survey'!F71&")") -> Appropriate with SAP / in Warranty (10) | I73: ='web survey'!U71 | J73: =IF(B73="FU-ACInstall","-",VLOOKUP(VALUE('web survey'!G71),ref!$E$24:$F$26,2,0)&" ("&'web survey'!G71&")") -> Jelas (5) | K73: =YEAR('web survey'!Z71)&"-"&IF(MONTH('web survey'!Z71)<10,"0"&MONTH('web survey'!Z71),MONTH('web survey'!Z71))&"-"&IF(DAY('web survey'!Z71)<10,"0"&DAY('web survey'!Z71),DAY('web survey'!Z71))&" "&IF(HOUR('web survey'!Z71)<10,"0"&HOUR('web survey'!Z71),HOUR('web survey'!Z71))&":"&IF(MINUTE('web survey'!Z71)<10,"0"&MINUTE('web survey'!Z71),MINUTE('web survey'!Z71))&(":00'") -> 2024-08-21 15:11:00' | N73: 70 | O73: FU-Z1-Eng | P73: 203903396 | Q73: Good (10) | S73: Good (5) | U73: Appropriate with SAP / in Warranty (10) | W73: Jelas (5) | X73: 21 Aug 2024 15:11
A74: =IF(B74="","",ROW()-COUNTBLANK($B$4:B74)-3) -> 71 | B74: ='web survey'!C72 -> FU-Z1-Eng | C74: ='web survey'!AA72 -> 100890510 | D74: =IF(B74="FU-ACInstall",VLOOKUP(VALUE('web survey'!D72),ref!$B$6:$C$7,2,0)&" ("&'web survey'!D72&")",VLOOKUP(VALUE('web survey'!D72),ref!$E$6:$F$10,2,0)&" ("&'web survey'!D72&")") -> Good (10) | E74: ='web survey'!S72 | F74: =IF(B74="FU-ACInstall",VLOOKUP(VALUE('web survey'!E72),ref!$B$10:$C$12,2,0)&" ("&'web survey'!E72&")",VLOOKUP(VALUE('web survey'!E72),ref!$E$13:$F$17,2,0)&" ("&'web survey'!E72&")") -> Very Good (10) | G74: ='web survey'!T72 | H74: =IF(B74="FU-ACInstall",VLOOKUP(VALUE('web survey'!F72),ref!$B$15:$C$17,2,0)&" ("&'web survey'!F72&")",VLOOKUP(VALUE('web survey'!F72),ref!$E$20:$F$21,2,0)&" ("&'web survey'!F72&")") -> Different with SAP (-10) | I74: ='web survey'!U72 | J74: =IF(B74="FU-ACInstall","-",VLOOKUP(VALUE('web survey'!G72),ref!$E$24:$F$26,2,0)&" ("&'web survey'!G72&")") -> Jelas (5) | K74: =YEAR('web survey'!Z72)&"-"&IF(MONTH('web survey'!Z72)<10,"0"&MONTH('web survey'!Z72),MONTH('web survey'!Z72))&"-"&IF(DAY('web survey'!Z72)<10,"0"&DAY('web survey'!Z72),DAY('web survey'!Z72))&" "&IF(HOUR('web survey'!Z72)<10,"0"&HOUR('web survey'!Z72),HOUR('web survey'!Z72))&":"&IF(MINUTE('web survey'!Z72)<10,"0"&MINUTE('web survey'!Z72),MINUTE('web survey'!Z72))&(":00'") -> 2024-08-21 15:10:00' | N74: 71 | O74: FU-Z1-Eng | P74: 100890510 | Q74: Good (10) | S74: Very Good (10) | U74: Different with SAP (-10) | W74: Jelas (5) | X74: 21 Aug 2024 15:10
A75: =IF(B75="","",ROW()-COUNTBLANK($B$4:B75)-3) -> 72 | B75: ='web survey'!C73 -> FU-Z1-Eng | C75: ='web survey'!AA73 -> 203889749 | D75: =IF(B75="FU-ACInstall",VLOOKUP(VALUE('web survey'!D73),ref!$B$6:$C$7,2,0)&" ("&'web survey'!D73&")",VLOOKUP(VALUE('web survey'!D73),ref!$E$6:$F$10,2,0)&" ("&'web survey'!D73&")") -> Good (10) | E75: ='web survey'!S73 | F75: =IF(B75="FU-ACInstall",VLOOKUP(VALUE('web survey'!E73),ref!$B$10:$C$12,2,0)&" ("&'web survey'!E73&")",VLOOKUP(VALUE('web survey'!E73),ref!$E$13:$F$17,2,0)&" ("&'web survey'!E73&")") -> Very Good (10) | G75: ='web survey'!T73 | H75: =IF(B75="FU-ACInstall",VLOOKUP(VALUE('web survey'!F73),ref!$B$15:$C$17,2,0)&" ("&'web survey'!F73&")",VLOOKUP(VALUE('web survey'!F73),ref!$E$20:$F$21,2,0)&" ("&'web survey'!F73&")") -> Appropriate with SAP / in Warranty (10) | I75: ='web survey'!U73 | J75: =IF(B75="FU-ACInstall","-",VLOOKUP(VALUE('web survey'!G73),ref!$E$24:$F$26,2,0)&" ("&'web survey'!G73&")") -> Jelas (5) | K75: =YEAR('web survey'!Z73)&"-"&IF(MONTH('web survey'!Z73)<10,"0"&MONTH('web survey'!Z73),MONTH('web survey'!Z73))&"-"&IF(DAY('web survey'!Z73)<10,"0"&DAY('web survey'!Z73),DAY('web survey'!Z73))&" "&IF(HOUR('web survey'!Z73)<10,"0"&HOUR('web survey'!Z73),HOUR('web survey'!Z73))&":"&IF(MINUTE('web survey'!Z73)<10,"0"&MINUTE('web survey'!Z73),MINUTE('web survey'!Z73))&(":00'") -> 2024-08-21 15:10:00' | N75: 72 | O75: FU-Z1-Eng | P75: 203889749 | Q75: Good (10) | S75: Very Good (10) | U75: Appropriate with SAP / in Warranty (10) | W75: Jelas (5) | X75: 21 Aug 2024 15:10
...

Sheet web survey
A1: id | B1: uid | C1: pid | D1: q1 value | E1: q2 value | F1: q3 value | G1: q4 value | H1: q5 value | I1: q6 value | J1: q7 value | K1: Total | L1: q1 text | M1: q2 text | N1: q3 text | O1: q4 text | P1: q5 text | Q1: q6 text | R1: q7text | S1: q1 answer | T1: q2 answer | U1: q3 answer | V1: q4 answer | W1: q5 answer | X1: q6 answer | Y1: q7 answer | Z1: date | AA1: ref | AB1: browser1 | AC1: ipaddress | AD1: ipaddress_country
A2: 133540 | B2: M | C2: FU-ACInstall | D2: 10 | E2: 10 | F2: 10 | K2: 30 | L2: Ya | M2: Baik / Dingin | N2: Baik | Z2: 21 Aug 2024 16:53 | AA2: TBS13A2400330 | AB2: Mozilla/5.0 (Linux; Android 10; K) AppleWebKit/537.36 (KHTML, like Gecko) SamsungBrowser/24.0 Chrome/117.0.0.0 Mobile Safari/537.36 | AC2: 114.10.147.146 | AD2: {"status":"success","country":"Indonesia","countryCode":"ID","region":"JB","regionName":"West Java","city":"Bandung","zip":"","lat":-6.9217,"lon":107.6071,"timezone":"Asia/Jakarta","isp":"PT. INDOSAT Tbk","org":"IOH B2B","as":"AS4761 INDOSAT Internet Network Provider","query":"114.10.147.146"}
